Workbook

Sheet summary_table_v26_27SIs
A1: Code | B1: Innovation Name | C1: Spatial Scale | D1: Indicator Number | E1: Indicator Name | F1: Description | G1: Metric | H1: Category | I1: slope_log | J1: slope_exp | K1: slope_lin | L1: log_t0 | M1: log_Dt | N1: log_K | O1: exp_a | P1: exp_c | Q1: lin_intercept | R1: log_r2 | S1: log_r2adj | T1: log_rmse | U1: log_mae | V1: exp_r2 | W1: exp_r2adj | X1: exp_rmse | Y1: exp_mae | Z1: lin_r2 | AA1: lin_r2adj | AB1: lin_rmse | AC1: lin_mae | AD1: n_data_points | AE1: n_non_zero_data_points | AF1: max_over_K | AG1: min_over_K | AH1: range_over_k | AI1: length_trimmed_series_years | AJ1: n_data_points_beyond_max | AK1: n_data_points_beyond_min | AL1: suspected_reversal_up2down | AM1: suspected_reversal_down2up | AN1: at_least_one_big_jump | AO1: autocorr_l1 | AP1: all_values_less_than_or_equal_to_1 | AQ1: all_values_less_than_or_equal_to_100 | AR1: C1_R2 | AS1: C2_threshold_non_zero_value_years | AT1: C3_pct_non_zero | AU1: C4_less_than_250_jump_in_second_half | AV1: C4_less_than_80_fall_in_second_half | AW1: C4_combined_less_than_80_fall_and_250_jump_in_second_half | AX1: C5_volatility_autocorrelation_lag1_threshold_0.7 | AY1: C6_{K_COVERAGE_THRESHOLD}_of_k_covered_by_data | AZ1: C7_lin_r2 | BA1: use_log_x | BB1: use_lin_x | BC1: use_log_y | BD1: use_lin_y | BE1: old GN scoring @retreat | BF1: old GN comments | BG1: old CW scoring @retreat | BH1: comments_fit_CW | BI1: comments_delete_CW | BJ1: comments_alternativeseries_CW | BK1: comments_transformations_CW | BL1: use_logfit_CW | BM1: use_linfit_CW | BN1: select_1.1_earegion_CW | BO1: select_1.1_allregions_CW | BP1: select_non1.1s_earegion_CW | BQ1: select_non1.1s_allregions_CW | BR1: GN final scoring | BS1: use_logfit_GN | BT1: use_linfit_GN | BU1: select_1.1_earegion_GN | BV1: select_1.1_allregions_GN | BW1: select_non1.1s_earegion_GN | BX1: select_non1.1s_allregions_GN | BY1: PDF page | BZ1: use_logfit_AGREE? | CA1: use_linfit_AGREE? | CB1: select_1.1_earegion_AGREE? | CC1: select_1.1_allregions_AGREE? | CD1: select_non1.1s_earegion_AGREE? | CE1: select_non1.1s_allregions_AGREE? | CF1: FINAL_AGREED | CG1: use_logfit_FIN | CH1: use_linfit_FIN | CI1: select_1.1_earegion_FIN | CJ1: select_1.1_allregions_FIN | CK1: select_non1.1s_earegion_FIN | CL1: select_non1.1s_allregions_FIN | CM1: CWnotes_6May | CN1: GN notes 9 may
A2: act_ams_1.1Ado_d063_m028 | B2: active mobility | C2: Amsterdam | D2: 1.1 | E2: Adoption over time | F2: Bike ownership | G2: % | H2: b7 | I2: 6.1161 | J2: 0.0054776 | K2: 0.0038502 | L2: 1984.7 | M2: 0.7185 | N2: 0.71167 | O2: 0.76729 | P2: 2018.3 | Q2: -7.0056 | R2: 0.67402 | S2: 0.34804 | T2: 0.022307 | U2: 0.018571 | V2: 0.78529 | W2: 0.67794 | X2: 0.018104 | Y2: 0.017715 | Z2: 0.79629 | AA2: 0.69443 | AB2: 0.017635 | AC2: 0.017232 | AD2: 7 | AE2: 7 | AF2: 1.0539 | AG2: 0.87119 | AH2: 0.18267 | AI2: 29 | AJ2: 1 | AK2: 6 | AL2: 0 | AM2: 0 | AN2: 0 | AO2: 0.86693 | AP2: 1 | AQ2: 1 | AR2: m | AS2: y | AT2: y | AU2: y | AV2: y | AW2: y | AX2: y | AY2: m | AZ2: y | BA2: m | BB2: y | BC2: n | BD2: y | BE2: 1 | BI2: 0 | BL2: 0 | BM2: 1 | BN2: 0 | BO2: 0 | BP2: 0 | BQ2: 0 | BS2: 0 | BT2: 1 | BU2: 0 | BV2: 0 | BW2: 0 | BX2: 0 | BY2: 1 | CG2: 0 | CH2: 1 | CI2: 0 | CJ2: 0 | CK2: 0 | CL2: 0 | CO2: means I've changed 0 to 1 or vice versa
A3: act_ams_1.1Ado_d121_m090 | B3: active mobility | C3: Amsterdam | D3: 1.1 | E3: Adoption over time | F3: Modal share of all trips by residents (bike) | G3: % trips by bike | H3: b7 | I3: -0.0023618 | J3: -0.0023613 | K3: -0.00056291 | L3: -1564.6 | M3: -1860.6 | N3: 1091.8 | O3: 0.67031 | P3: 1566.4 | Q3: 1.3672 | R3: 0.17886 | S3: -0.31382 | T3: 0.03044 | U3: 0.027427 | V3: 0.17886 | W3: -0.094847 | X3: 0.03044 | Y3: 0.027427 | Z3: 0.16499 | AA3: -0.11334 | AB3: 0.030696 | AC3: 0.027808 | AD3: 9 | AE3: 9 | AF3: 0.00028395 | AG3: 0.00018319 | AH3: 0.00010076 | AI3: 84 | AJ3: 8 | AK3: 2 | AL3: 0 | AM3: 0 | AN3: 0 | AO3: 0.84023 | AP3: 1 | AQ3: 1 | AR3: n | AS3: y | AT3: y | AU3: y | AV3: y | AW3: y | AX3: y | AY3: m | AZ3: m | BA3: n | BB3: m | BC3: n | BD3: m | BE3: 2 | BI3: 0 | BL3: 1 | BM3: 1 | BN3: 0 | BO3: 0 | BP3: 0 | BQ3: 0 | BS3: 1 | BT3: 1 | BU3: 0 | BV3: 0 | BW3: 0 | BX3: 0 | BY3: 2 | CG3: 1 | CH3: 1 | CI3: 0 | CJ3: 0 | CK3: 0 | CL3: 0 | CO3: means problem, dicuss with GN
A4: act_ams_1.1Ado_d122_m091 | B4: active mobility | C4: Amsterdam | D4: 1.1 | E4: Adoption over time | F4: Modal share of all trips by residents (walk) | G4: % trips by walking | H4: b7 | I4: -16.742 | J4: -0.0042167 | K4: -0.0010874 | L4: 1996.2 | M4: -0.26248 | N4: 0.272 | O4: 0.083316 | P4: 2247.9 | Q4: 2.4124 | R4: -4.8878 | S4: -8.4205 | T4: 0.16055 | U4: 0.13267 | V4: 0.1654 | W4: -0.1128 | X4: 0.060446 | Y4: 0.045681 | Z4: 0.15869 | AA4: -0.12175 | AB4: 0.060688 | AC4: 0.045795 | AD4: 9 | AE4: 9 | AF4: 1.2868 | AG4: 0.44118 | AH4: 0.84559 | AI4: 84 | AJ4: 8 | AK4: 7 | AL4: 0 | AM4: 1 | AN4: 1 | AO4: 0.78584 | AP4: 1 | AQ4: 1 | AR4: n | AS4: y | AT4: y | AU4: y | AV4: y | AW4: y | AX4: y | AY4: y | AZ4: m | BA4: n | BB4: m | BC4: n | BD4: m | BE4: 4 | BG4: ok, use logfit | BI4: 0 | BL4: 1 | BM4: 1 | BN4: 0 | BO4: 0 | BP4: 0 | BQ4: 0 | BS4: 1 | BT4: 1 | BU4: 0 | BV4: 0 | BW4: 0 | BX4: 0 | BY4: 3 | CG4: 0 | CH4: 1 | CI4: 0 | CJ4: 0 | CK4: 0 | CL4: 0 | CM4: SdS: fit partial from 1979 (drop 1930 peak year) | CO4: means new coding for changed indicators post Feb
A5: act_ams_1.1Ado_d332_m185 | B5: active mobility | C5: Amsterdam | D5: 1.1 | E5: Adoption over time | F5: % trips by walking and biking | G5: market share | H5: b7 | I5: -0.0087911 | J5: -0.0033221 | K5: -0.0016503 | L5: 2033.8 | M5: -499.87 | N5: 0.83407 | O5: 0.0026073 | P5: 3568.5 | Q5: 3.7796 | R5: 0.19777 | S5: -0.28356 | T5: 0.078513 | U5: 0.059173 | V5: 0.22115 | W5: -0.038465 | X5: 0.07736 | Y5: 0.058997 | Z5: 0.20825 | AA5: -0.055671 | AB5: 0.077999 | AC5: 0.059339 | AD5: 9 | AE5: 9 | AF5: 0.79131 | AG5: 0.40764 | AH5: 0.38366 | AI5: 84 | AJ5: 8 | AK5: 7 | AL5: 0 | AM5: 1 | AN5: 0 | AO5: 0.82455 | AP5: 1 | AQ5: 1 | AR5: n | AS5: y | AT5: y | AU5: y | AV5: y | AW5: y | AX5: y | AY5: y | AZ5: m | BA5: n | BB5: m | BC5: n | BD5: m | BI5: 0 | BJ5: prefer-relative | BK5: transformed-marketshare | BL5: 1 | BM5: 1 | BN5: 0 | BO5: 1 | BP5: 0 | BQ5: 0 | BS5: 1 | BT5: 1 | BU5: 0 | BV5: 1 | BW5: 0 | BX5: 0 | BY5: 4 | CG5: 1 | CH5: 1 | CI5: 0 | CJ5: 0 | CK5: 0 | CL5: 0 | CO5: means didn't survive _v24 to _v25 transfer
A6: act_ams_1.1Ado_d359_m091 | B6: active mobility | C6: Amsterdam | D6: 1.1 | E6: Adoption over time | F6: Modal share of all trips by residents (walk) EXCLUDING 1930 | G6: % trips by walking | H6: b7 | I6: 1.9434 | J6: 0.0020703 | K6: 0.00060028 | L6: 1970.1 | M6: 2.2612 | N6: 0.25429 | O6: 0.068688 | P6: 1396.9 | Q6: -0.96066 | R6: 0.56052 | S6: 0.23091 | T6: 0.039325 | U6: 0.033214 | V6: 0.014739 | W6: -0.37937 | X6: 0.05888 | Y6: 0.051788 | Z6: 0.018126 | AA6: -0.37462 | AB6: 0.058779 | AC6: 0.052101 | AD6: 8 | AE6: 8 | AF6: 1.2191 | AG6: 0.47191 | AH6: 0.74719 | AI6: 44 | AJ6: 6 | AK6: 7 | AL6: 1 | AM6: 0 | AN6: 1 | AO6: 0.89904 | AP6: 1 | AQ6: 1 | AR6: m | AS6: y | AT6: y | AU6: y | AV6: y | AW6: y | AX6: y | AY6: y | AZ6: m | BA6: m | BB6: m | CG6: 0 | CH6: 1 | CI6: 0 | CJ6: 0 | CK6: 0 | CL6: 0
A7: act_ams_1.1Ado_d360_m185 | B7: active mobility | C7: Amsterdam | D7: 1.1 | E7: Adoption over time | F7: % trips by walking and biking EXCLUDING 1930 | G7: market share | H7: b7 | I7: 1.0857 | J7: 0.0026517 | K7: 0.0013983 | L7: 1969.3 | M7: 4.0475 | N7: 0.49714 | O7: 0.10663 | P7: 1430.8 | Q7: -2.3135 | R7: 0.54632 | S7: 0.20607 | T7: 0.047359 | U7: 0.036072 | V7: 0.062786 | W7: -0.3121 | X7: 0.068069 | Y7: 0.06083 | Z7: 0.070004 | AA7: -0.30199 | AB7: 0.067806 | AC7: 0.060625 | AD7: 8 | AE7: 8 | AF7: 1.1264 | AG7: 0.68391 | AH7: 0.44253 | AI7: 44 | AJ7: 4 | AK7: 7 | AL7: 1 | AM7: 0 | AN7: 0 | AO7: 0.89687 | AP7: 1 | AQ7: 1 | AR7: m | AS7: y | AT7: y | AU7: y | AV7: y | AW7: y | AX7: y | AY7: y | AZ7: m | BA7: m | BB7: m | CG7: 0 | CH7: 1 | CI7: 0 | CJ7: 1 | CK7: 0 | CL7: 0
A8: act_bei_1.1Ado_d060_m028 | B8: active mobility | C8: Beijing | D8: 1.1 | E8: Adoption over time | F8: Bicycle modal share | G8: % | H8: b7 | I8: -128.93 | J8: -0.00040147 | K8: -0.01425 | L8: 1999.7 | M8: -0.034083 | N8: 0.5403 | O8: -1544.5 | P8: -152600 | Q8: 28.852 | R8: -3.1777 | S8: 9.3553 | T8: 0.25892 | U8: 0.205 | V8: -9.2413 | W8: =-inf -> #NAME? | X8: 0.4054 | Y8: 0.3851 | Z8: 0.96449 | AA8: =-inf -> #NAME? | AB8: 0.023871 | AC8: 0.0221 | AD8: 3 | AE8: 3 | AF8: 1 | AG8: 0.42569 | AH8: 0.57431 | AI8: 22 | AJ8: 2 | AK8: 0 | AL8: 0 | AM8: 0 | AN8: 0 | AO8: 0.60149 | AP8: 1 | AQ8: 1 | AR8: n | AS8: m | AT8: y | AU8: y | AV8: y | AW8: y | AX8: m | AY8: y | AZ8: y | BA8: n | BB8: m | BC8: m | BD8: m | BE8: 2 | BI8: 0 | BL8: 1 | BM8: 1 | BN8: 0 | BO8: 0 | BP8: 0 | BQ8: 0 | BS8: 1 | BT8: 1 | BU8: 0 | BV8: 0 | BW8: 0 | BX8: 0 | BY8: 5 | CG8: 0 | CH8: 1 | CI8: 0 | CJ8: 0 | CK8: 0 | CL8: 0
A9: act_bei_1.1Ado_d332_m185 | B9: active mobility | C9: Beijing | D9: 1.1 | E9: Adoption over time | F9: % trips by walking and biking | G9: market share | H9: b7 | I9: -128.93 | J9: -0.00040147 | K9: -0.01425 | L9: 1999.7 | M9: -0.034083 | N9: 0.5403 | O9: -1544.5 | P9: -152600 | Q9: 28.852 | R9: -3.1777 | S9: 9.3553 | T9: 0.25892 | U9: 0.205 | V9: -9.2413 | W9: =-inf -> #NAME? | X9: 0.4054 | Y9: 0.3851 | Z9: 0.96449 | AA9: =-inf -> #NAME? | AB9: 0.023871 | AC9: 0.0221 | AD9: 3 | AE9: 3 | AF9: 1 | AG9: 0.42569 | AH9: 0.57431 | AI9: 22 | AJ9: 2 | AK9: 0 | AL9: 0 | AM9: 0 | AN9: 0 | AO9: 0.60149 | AP9: 1 | AQ9: 1 | AR9: n | AS9: m | AT9: y | AU9: y | AV9: y | AW9: y | AX9: m | AY9: y | AZ9: y | BA9: n | BB9: m | BC9: m | BD9: m | BI9: 0 | BJ9: prefer-relative | BK9: transformed-marketshare | BL9: 1 | BM9: 1 | BN9: 0 | BO9: 1 | BP9: 0 | BQ9: 0 | BS9: 1 | BT9: 1 | BU9: 0 | BV9: 1 | BW9: 0 | BX9: 0 | BY9: 6 | CG9: 0 | CH9: 1 | CI9: 0 | CJ9: 1 | CK9: 0 | CL9: 0
A10: act_chi_1.1Ado_d061_m002 | B10: active mobility | C10: China | D10: 1.1 | E10: Adoption over time | F10: Bicycle ownership | G10: # bikes per hundred households | H10: b7 | I10: 15.465 | J10: 0.020393 | K10: 2.6286 | L10: 1814.4 | M10: 0.28415 | N10: 110.03 | O10: 3.2025 | P10: 1817.7 | Q10: -5121 | R10: 0 | S10: =-inf -> #NAME? | T10: 61.847 | U10: 47.333 | V10: 0.20425 | W10: -1.3873 | X10: 55.17 | Y10: 49.509 | Z10: 0.23213 | AA10: -1.3036 | AB10: 54.195 | AC10: 50.322 | AD10: 4 | AE10: 4 | AF10: 1.7918 | AG10: 0.20794 | AH10: 1.5839 | AI10: 30 | AJ10: 1 | AK10: 2 | AL10: 1 | AM10: 1 | AN10: 1 | AO10: 0.47132 | AP10: 0 | AQ10: 0 | AR10: n | AS10: m | AT10: y | AU10: m | AV10: y | AW10: m | AX10: m | AY10: y | AZ10: m | BA10: n | BB10: m | BC10: m | BD10: m | BE10: 4 | BG10: reject, too few points | BI10: 0 | BL10: 0 | BM10: 1 | BN10: 0 | BO10: 0 | BP10: 0 | BQ10: 0 | BS10: 0 | BT10: 1 | BU10: 0 | BV10: 0 | BW10: 0 | BX10: 0 | BY10: 7 | CG10: 0 | CH10: 1 | CI10: 0 | CJ10: 0 | CK10: 0 | CL10: 0
A11: act_chi_3.2Adc_d062_m003 | B11: active mobility | C11: China | D11: 3.2 | E11: Adopter characteristics | F11: Bicycle ownership among income groups | G11: # bikes per hundred households (highest 10% income) | H11: b7 | I11: -0.25049 | J11: -0.017188 | K11: -3.0744 | L11: 2008 | M11: -17.543 | N11: 187.66 | O11: 280.33 | P11: 1964.3 | Q11: 6300.3 | R11: 0.82934 | S11: =-inf -> #NAME? | T11: 12.667 | U11: 10.677 | V11: 0.51703 | W11: -0.4489 | X11: 21.309 | Y11: 19.229 | Z11: 0.56489 | AA11: -0.30533 | AB11: 20.226 | AC11: 18.246 | AD11: 4 | AE11: 4 | AF11: 1.0823 | AG11: 0.62879 | AH11: 0.45353 | AI11: 21 | AJ11: 2 | AK11: 0 | AL11: 1 | AM11: 0 | AN11: 0 | AO11: 0.78003 | AP11: 0 | AQ11: 0 | AR11: y | AS11: m | AT11: y | AU11: y | AV11: y | AW11: y | AX11: y | AY11: y | AZ11: y | BA11: m | BB11: m | BC11: m | BD11: m | BE11: 2 | BI11: 0 | BL11: 0 | BM11: 1 | BS11: 1 | BT11: 1 | BU11: 0 | BV11: 0 | BW11: 0 | BX11: 0 | BY11: 8 | BZ11: check | CG11: 1 | CH11: 1 | CI11: 0 | CJ11: 0 | CK11: 0 | CL11: 0
A12: act_chi_3.2Adc_d062_m004 | B12: active mobility | C12: China | D12: 3.2 | E12: Adopter characteristics | F12: Bicycle ownership among income groups | G12: # bikes per hundred households (lowest 10% income) | H12: b7 | I12: -2.6167 | J12: -0.0083411 | K12: -1.3736 | L12: 2006.3 | M12: -1.6794 | N12: 157.06 | O12: 227.52 | P12: 1941.8 | Q12: 2886.7 | R12: 0.61758 | S12: =-inf -> #NAME? | T12: 16.895 | U12: 12.122 | V12: 0.12506 | W12: -1.6248 | X12: 25.555 | Y12: 25.04 | Z12: 0.14203 | AA12: -1.5739 | AB12: 25.306 | AC12: 24.861 | AD12: 4 | AE12: 4 | AF12: 1.1498 | AG12: 0.68431 | AH12: 0.46548 | AI12: 21 | AJ12: 2 | AK12: 0 | AL12: 1 | AM12: 0 | AN12: 0 | AO12: 0.80089 | AP12: 0 | AQ12: 0 | AR12: m | AS12: m | AT12: y | AU12: y | AV12: y | AW12: y | AX12: y | AY12: y | AZ12: m | BA12: m | BB12: m | BC12: m | BD12: m | BE12: 2 | BI12: 0 | BL12: 0 | BM12: 1 | BS12: 0 | BT12: 1 | BU12: 0 | BV12: 0 | BW12: 0 | BX12: 0 | BY12: 9 | CG12: 0 | CH12: 1 | CI12: 0 | CJ12: 0 | CK12: 0 | CL12: 0
A13: act_chi_3.2Adc_d062_m005 | B13: active mobility | C13: China | D13: 3.2 | E13: Adopter characteristics | F13: Bicycle ownership among income groups | G13: # bikes per hundred households (middle income groups) | H13: b7 | I13: -0.35805 | J13: -0.013207 | K13: -2.4015 | L13: 2007.8 | M13: -12.273 | N13: 181.57 | O13: 267.65 | P13: 1958.3 | Q13: 4957 | R13: 0.75315 | S13: =-inf -> #NAME? | T13: 14.824 | U13: 11.464 | V13: 0.32729 | W13: -1.0181 | X13: 24.472 | Y13: 23.3 | Z13: 0.364 | AA13: -0.90799 | AB13: 23.795 | AC13: 22.74 | AD13: 4 | AE13: 4 | AF13: 1.1186 | AG13: 0.65538 | AH13: 0.46323 | AI13: 21 | AJ13: 2 | AK13: 0 | AL13: 1 | AM13: 0 | AN13: 0 | AO13: 0.79113 | AP13: 0 | AQ13: 0 | AR13: y | AS13: m | AT13: y | AU13: y | AV13: y | AW13: y | AX13: y | AY13: y | AZ13: y | BA13: m | BB13: m | BC13: m | BD13: m | BE13: 2 | BI13: 0 | BL13: 0 | BM13: 1 | BS13: 1 | BT13: 1 | BU13: 0 | BV13: 0 | BW13: 0 | BX13: 1 | BY13: 10 | BZ13: check | CG13: 1 | CH13: 1 | CI13: 0 | CJ13: 0 | CK13: 0 | CL13: 1
A14: act_chi_4.1Sal_d213_m100 | B14: active mobility | C14: China | D14: 4.1 | E14: Knowledge Flows (social networks) | F14: annualised Google search frequency (index 100=monthly max.) | G14: Index 0-100 | H14: b7 | I14: 2.095 | J14: 0.076912 | K14: 3.6253 | L14: 2013.4 | M14: 2.0976 | N14: 61.747 | O14: 0.65739 | P14: 1963.6 | Q14: -7267.6 | R14: 0.79934 | S14: 0.76393 | T14: 14.129 | U14: 9.9398 | V14: 0.36338 | W14: 0.29265 | X14: 25.166 | Y14: 21.242 | Z14: 0.48439 | AA14: 0.4271 | AB14: 22.649 | AC14: 17.771 | AD14: 21 | AE14: 20 | AF14: 1.6195 | AG14: 0.017461 | AH14: 1.6021 | AI14: 21 | AJ14: 8 | AK14: 20 | AL14: 1 | AM14: 0 | AN14: 1 | AO14: 0.93024 | AP14: 0 | AQ14: 1 | AR14: y | AS14: y | AT14: y | AU14: y | AV14: y | AW14: y | AX14: y | AY14: y | AZ14: y | BA14: y | BB14: y | BC14: y | BD14: y | BI14: 0 | BJ14: hide | BK14: original | BL14: 1 | BM14: 1 | BN14: 0 | BO14: 0 | BP14: 0 | BQ14: 0 | BS14: 1 | BT14: 0 | BU14: 0 | BV14: 0 | BW14: 0 | BX14: 0 | BY14: 11 | CA14: check | CG14: 1 | CH14: 1 | CI14: 0 | CJ14: 0 | CK14: 0 | CL14: 0
A15: act_chi_4.1Sal_d239_m153 | B15: active mobility | C15: China | D15: 4.1 | E15: Knowledge Flows (social networks) | F15: Partial up to max annualised Google search frequency (index 100=monthly max.) | G15: Partial up to max Index 0-100 | H15: b7 | I15: 1.0431 | J15: 0.49369 | K15: 6.5779 | L15: 2014.6 | M15: 4.213 | N15: 123.43 | O15: 0.019473 | P15: 1998.6 | Q15: -13201 | R15: 0.99639 | S15: 0.99519 | T15: 1.8903 | U15: 1.5688 | V15: 0.97515 | W15: 0.97018 | X15: 4.9601 | Y15: 3.8128 | Z15: 0.61177 | AA15: 0.53412 | AB15: 19.606 | AC15: 16.835 | AD15: 13 | AE15: 12 | AF15: 0.81017 | AG15: 0.0087349 | AH15: 0.80143 | AI15: 13 | AJ15: 0 | AK15: 12 | AL15: 0 | AM15: 0 | AN15: 1 | AO15: 0.66032 | AP15: 0 | AQ15: 1 | AR15: y | AS15: y | AT15: y | AU15: y | AV15: y | AW15: y | AX15: m | AY15: y | AZ15: y | BA15: m | BB15: m | BC15: y | BD15: y | BI15: 0 | BJ15: prefer | BK15: transformed-partial | BL15: 1 | BM15: 1 | BN15: 0 | BO15: 0 | BP15: 0 | BQ15: 1 | BS15: 1 | BT15: 1 | BU15: 0 | BV15: 0 | BW15: 0 | BX15: 1 | BY15: 12 | CG15: 1 | CH15: 1 | CI15: 0 | CJ15: 0 | CK15: 0 | CL15: 1
A16: act_cop_1.1Ado_d121_m090 | B16: active mobility | C16: Copenhagen | D16: 1.1 | E16: Adoption over time | F16: Modal share of all trips by residents (bike) | G16: % trips by bike | H16: b7 | I16: 0.014241 | J16: 0.0012979 | K16: 0.0033675 | L16: 2734.2 | M16: 308.58 | N16: 8643.2 | O16: 1555.1 | P16: 157450 | Q16: -6.4834 | R16: 0.784 | S16: =-inf -> #NAME? | T16: 0.018985 | U16: 0.018338 | V16: -38.206 | W16: -116.62 | X16: 0.25578 | Y16: 0.2525 | Z16: 0.7454 | AA16: 0.23619 | AB16: 0.020612 | AC16: 0.020026 | AD16: 4 | AE16: 4 | AF16: 3.7023e-05 | AG16: 2.5454e-05 | AH16: 1.157e-05 | AI16: 28 | AJ16: 0 | AK16: 3 | AL16: 0 | AM16: 0 | AN16: 0 | AO16: 0.7008 | AP16: 1 | AQ16: 1 | AR16: y | AS16: m | AT16: y | AU16: y | AV16: y | AW16: y | AX16: y | AY16: m | AZ16: y | BA16: m | BB16: m | BC16: m | BD16: m | BE16: 2 | BI16: 0 | BL16: 1 | BM16: 1 | BN16: 0 | BO16: 0 | BP16: 0 | BQ16: 0 | BS16: 1 | BT16: 1 | BU16: 0 | BV16: 0 | BW16: 0 | BX16: 0 | BY16: 13 | CG16: 1 | CH16: 1 | CI16: 0 | CJ16: 0 | CK16: 0 | CL16: 0
A17: act_cop_1.1Ado_d122_m091 | B17: active mobility | C17: Copenhagen | D17: 1.1 | E17: Adoption over time | F17: Modal share of all trips by residents (walk) | G17: % trips by walking | H17: b7 | I17: 0.0018687 | J17: 0.0010136 | K17: 0.00030769 | L17: 5039 | M17: 2351.6 | N17: 54.298 | O17: 1555.1 | P17: 157440 | Q17: -0.43046 | R17: 0.007873 | S17: =-inf -> #NAME? | T17: 0.038254 | U17: 0.031585 | V17: -23.203 | W17: -71.61 | X17: 0.18894 | Y17: 0.185 | Z17: 0.0070404 | AA17: -1.9789 | AB17: 0.03827 | AC17: 0.031692 | AD17: 4 | AE17: 4 | AF17: 0.0040517 | AG17: 0.00221 | AH17: 0.0018417 | AI17: 28 | AJ17: 3 | AK17: 2 | AL17: 0 | AM17: 1 | AN17: 0 | AO17: 0.63305 | AP17: 1 | AQ17: 1 | AR17: n | AS17: m | AT17: y | AU17: y | AV17: y | AW17: y | AX17: m | AY17: m | AZ17: m | BA17: n | BB17: m | BC17: n | BD17: m | BE17: 4 | BG17: ok, use logfit | BI17: 0 | BL17: 0 | BM17: 0 | BN17: 0 | BO17: 0 | BP17: 0 | BQ17: 0 | BS17: 1 | BT17: 1 | BU17: 0 | BV17: 0 | BW17: 0 | BX17: 0 | BY17: 14 | BZ17: check | CA17: check | CG17: 1 | CH17: 1 | CI17: 0 | CJ17: 0 | CK17: 0 | CL17: 0
A18: act_cop_1.1Ado_d332_m185 | B18: active mobility | C18: Copenhagen | D18: 1.1 | E18: Adoption over time | F18: % trips by walking and biking | G18: market share | H18: b7 | I18: 0.015233 | J18: 0.0013115 | K18: 0.0036752 | L18: 2016.9 | M18: 288.48 | N18: 1 | O18: 1555.2 | P18: 157440 | Q18: -6.9138 | R18: 0.36641 | S18: =-inf -> #NAME? | T18: 0.051084 | U18: 0.045033 | V18: -46.472 | W18: -141.42 | X18: 0.44218 | Y18: 0.4375 | Z18: 0.35971 | AA18: -0.92086 | AB18: 0.051353 | AC18: 0.045256 | AD18: 4 | AE18: 4 | AF18: 0.52 | AG18: 0.34 | AH18: 0.18 | AI18: 28 | AJ18: 0 | AK18: 2 | AL18: 0 | AM18: 1 | AN18: 0 | AO18: 0.6861 | AP18: 1 | AQ18: 1 | AR18: m | AS18: m | AT18: y | AU18: y | AV18: y | AW18: y | AX18: m | AY18: m | AZ18: y | BA18: m | BB18: m | BC18: m | BD18: m | BI18: 0 | BJ18: prefer-relative | BK18: transformed-marketshare | BL18: 1 | BM18: 1 | BN18: 0 | BO18: 1 | BP18: 0 | BQ18: 0 | BS18: 1 | BT18: 1 | BU18: 0 | BV18: 1 | BW18: 0 | BX18: 0 | BY18: 15 | CG18: 1 | CH18: 1 | CI18: 0 | CJ18: 1 | CK18: 0 | CL18: 0
A19: act_den_4.1Sal_d213_m100 | B19: active mobility | C19: Denmark | D19: 4.1 | E19: Knowledge Flows (social networks) | F19: annualised Google search frequency (index 100=monthly max.) | G19: Index 0-100 | H19: b7 | I19: 5.3821 | J19: 0.046164 | K19: 2.6871 | L19: 2011.1 | M19: 0.81649 | N19: 61.49 | O19: 1.3191 | P19: 1940.1 | Q19: -5371.1 | R19: 0.6915 | S19: 0.63706 | T19: 17.672 | U19: 13.516 | V19: 0.18602 | W19: 0.095577 | X19: 28.705 | Y19: 24.86 | Z19: 0.26155 | AA19: 0.1795 | AB19: 27.341 | AC19: 23.166 | AD19: 21 | AE19: 20 | AF19: 1.6263 | AG19: 0.0025937 | AH19: 1.6237 | AI19: 21 | AJ19: 9 | AK19: 16 | AL19: 1 | AM19: 1 | AN19: 1 | AO19: 0.94961 | AP19: 0 | AQ19: 1 | AR19: m | AS19: y | AT19: y | AU19: y | AV19: y | AW19: y | AX19: y | AY19: y | AZ19: m | BA19: m | BB19: m | BC19: m | BD19: m | BI19: 0 | BJ19: hide | BK19: original | BL19: 1 | BM19: 1 | BN19: 0 | BO19: 0 | BP19: 0 | BQ19: 0 | BS19: 1 | BT19: 0 | BU19: 0 | BV19: 0 | BW19: 0 | BX19: 0 | BY19: 16 | CA19: check | CG19: 1 | CH19: 1 | CI19: 0 | CJ19: 0 | CK19: 0 | CL19: 0
A20: act_den_4.1Sal_d239_m153 | B20: active mobility | C20: Denmark | D20: 4.1 | E20: Knowledge Flows (social networks) | F20: Partial up to max annualised Google search frequency (index 100=monthly max.) | G20: Partial up to max Index 0-100 | H20: b7 | I20: 1.43 | J20: 0.31327 | K20: 9.5766 | L20: 2011.7 | M20: 3.073 | N20: 98.11 | O20: 0.0079377 | P20: 1984.4 | Q20: -19211 | R20: 0.987 | S20: 0.98212 | T20: 4.3211 | U20: 3.2716 | V20: 0.89193 | W20: 0.86791 | X20: 12.458 | Y20: 10.933 | Z20: 0.76106 | AA20: 0.70796 | AB20: 18.524 | AC20: 16.71 | AD20: 12 | AE20: 11 | AF20: 1.0193 | AG20: 0.0016256 | AH20: 1.0176 | AI20: 12 | AJ20: 0 | AK20: 7 | AL20: 0 | AM20: 1 | AN20: 1 | AO20: 0.79251 | AP20: 0 | AQ20: 1 | AR20: y | AS20: y | AT20: y | AU20: y | AV20: y | AW20: y | AX20: y | AY20: y | AZ20: y | BA20: y | BB20: y | BC20: y | BD20: y | BI20: 0 | BJ20: prefer | BK20: transformed-partial | BL20: 1 | BM20: 1 | BN20: 0 | BO20: 0 | BP20: 0 | BQ20: 1 | BS20: 1 | BT20: 1 | BU20: 0 | BV20: 0 | BW20: 0 | BX20: 1 | BY20: 17 | CG20: 1 | CH20: 1 | CI20: 0 | CJ20: 0 | CK20: 0 | CL20: 1
A21: act_glo_3.3Sci_d235_m020 | B21: active mobility | C21: Global | D21: 3.3 | E21: Risk & Uncertainty (Shared Expectations) | F21: scientific publications | G21: # publications | H21: b7 | I21: 0.098082 | J21: 0.075253 | K21: 339.27 | L21: 2026.2 | M21: 44.804 | N21: 47724 | O21: 0.0059608 | P21: 1822.8 | Q21: -672090 | R21: 0.98746 | S21: 0.98672 | T21: 674.84 | U21: 429.14 | V21: 0.98322 | W21: 0.98257 | X21: 780.65 | Y21: 440.85 | Z21: 0.79877 | AA21: 0.79103 | AB21: 2703.1 | AC21: 2313.6 | AD21: 55 | AE21: 55 | AF21: 0.43486 | AG21: 0.0017811 | AH21: 0.43307 | AI21: 55 | AJ21: 2 | AK21: 54 | AL21: 0 | AM21: 0 | AN21: 1 | AO21: 0.95068 | AP21: 0 | AQ21: 0 | AR21: y | AS21: y | AT21: y | AU21: y | AV21: y | AW21: y | AX21: y | AY21: y | AZ21: y | BA21: y | BB21: y | BC21: y | BD21: y | BH21: good; only available global, apply to all EA regions | BI21: 0 | BL21: 1 | BM21: 1 | BN21: 0 | BO21: 0 | BP21: 1 | BQ21: 1 | BS21: 1 | BT21: 1 | BU21: 0 | BV21: 0 | BW21: 1 | BX21: 1 | BY21: 18 | CG21: 1 | CH21: 1 | CI21: 0 | CJ21: 0 | CK21: 1 | CL21: 1
A22: act_net_1.1Ado_d167_m096 | B22: active mobility | C22: The Netherlands | D22: 1.1 | E22: Adoption over time | F22: Passenger kilometres travelled by¬†bike | G22: Billion p.km | H22: b7 | I22: 0.17814 | J22: 0.013226 | K22: 0.21626 | L22: 1998.6 | M22: 24.668 | N22: 17.492 | O22: 6.6659 | P22: 1947.9 | Q22: -419.53 | R22: 0.71531 | S22: 0.64961 | T22: 0.77647 | U22: 0.65529 | V22: 0.60366 | W22: 0.54704 | X22: 0.91615 | Y22: 0.789 | Z22: 0.62081 | AA22: 0.56664 | AB22: 0.89611 | AC22: 0.75497 | AD22: 17 | AE22: 17 | AF22: 1.0233 | AG22: 0.79466 | AH22: 0.22868 | AI22: 18 | AJ22: 0 | AK22: 16 | AL22: 0 | AM22: 0 | AN22: 0 | AO22: 0.93926 | AP22: 0 | AQ22: 1 | AR22: y | AS22: y | AT22: y | AU22: y | AV22: y | AW22: y | AX22: y | AY22: y | AZ22: y | BA22: y | BB22: y | BC22: y | BD22: y | BE22: 1 | BI22: 0 | BJ22: prefer-absolute | BL22: 1 | BM22: 1 | BN22: 2 | BO22: 2 | BP22: 0 | BQ22: 0 | BS22: 1 | BT22: 1 | BU22: 0 | BV22: 0 | BW22: 0 | BX22: 0 | BY22: 19 | CG22: 1 | CH22: 1 | CI22: 0 | CJ22: 0 | CK22: 0 | CL22: 0
A23: act_net_1.1Ado_d168_m096 | B23: active mobility | C23: The Netherlands | D23: 1.1 | E23: Adoption over time | F23: Passenger kilometres travelled by¬†foot | G23: Billion p.km | H23: b7 | I23: 0.046231 | J23: 0.04623 | K23: 0.21548 | L23: 2244.5 | M23: 95.054 | N23: 206610 | O23: 7.9825 | P23: 2024.7 | Q23: -428.98 | R23: 0.82968 | S23: 0.79038 | T23: 0.52885 | U23: 0.38906 | V23: 0.82968 | W23: 0.80535 | X23: 0.52885 | Y23: 0.38906 | Z23: 0.7949 | AA23: 0.7656 | AB23: 0.58034 | AC23: 0.44108 | AD23: 17 | AE23: 17 | AF23: 3.9204e-05 | AG23: 1.6456e-05 | AH23: 2.2748e-05 | AI23: 18 | AJ23: 1 | AK23: 16 | AL23: 0 | AM23: 0 | AN23: 0 | AO23: 0.92009 | AP23: 0 | AQ23: 1 | AR23: y | AS23: y | AT23: y | AU23: y | AV23: y | AW23: y | AX23: y | AY23: m | AZ23: y | BA23: m | BB23: y | BC23: m | BD23: y | BE23: 2 | BI23: 0 | BL23: 1 | BM23: 1 | BN23: 0 | BO23: 0 | BP23: 0 | BQ23: 0 | BS23: 1 | BT23: 1 | BU23: 0 | BV23: 0 | BW23: 0 | BX23: 0 | BY23: 20 | CG23: 1 | CH23: 1 | CI23: 0 | CJ23: 0 | CK23: 0 | CL23: 0
A24: act_net_1.1Ado_d332_m185 | B24: active mobility | C24: The Netherlands | D24: 1.1 | E24: Adoption over time | F24: % trips by walking and biking | G24: market share | H24: b7 | I24: 0.070443 | J24: 0.026144 | K24: 0.0035545 | L24: 2006.4 | M24: 62.383 | N24: 0.21832 | O24: 0.00085118 | P24: 1820 | Q24: -7.0219 | R24: 0.97061 | S24: 0.96383 | T24: 0.0032828 | U24: 0.0025168 | V24: 0.96078 | W24: 0.95518 | X24: 0.0037921 | Y24: 0.0030679 | Z24: 0.96855 | AA24: 0.96406 | AB24: 0.0033959 | AC24: 0.0025786 | AD24: 17 | AE24: 17 | AF24: 0.7503 | AG24: 0.49115 | AH24: 0.25914 | AI24: 18 | AJ24: 0 | AK24: 16 | AL24: 0 | AM24: 0 | AN24: 0 | AO24: 0.93891 | AP24: 1 | AQ24: 1 | AR24: y | AS24: y | AT24: y | AU24: y | AV24: y | AW24: y | AX24: y | AY24: y | AZ24: y | BA24: y | BB24: y | BC24: y | BD24: y | BI24: 0 | BJ24: prefer-relative | BK24: transformed-marketshare | BL24: 1 | BM24: 1 | BN24: 1 | BO24: 1 | BP24: 0 | BQ24: 0 | BS24: 1 | BT24: 1 | BU24: 1 | BV24: 1 | BW24: 0 | BX24: 0 | BY24: 21 | CG24: 1 | CH24: 1 | CI24: 1 | CJ24: 1 | CK24: 0 | CL24: 0
A25: act_net_2.9Int_d133_m139 | B25: active mobility | C25: The Netherlands | D25: 2.9 | E25: Interdependence with hardware | F25: Number of bicycles | G25: million | H25: b7 | I25: 0.049239 | J25: 0.016526 | K25: 0.34781 | L25: 1998.8 | M25: 89.248 | N25: 31.855 | O25: 5.1298 | P25: 1927.5 | Q25: -678.94 | R25: 0.87013 | S25: 0.84416 | T25: 0.79224 | U25: 0.66204 | V25: 0.85896 | W25: 0.84133 | X25: 0.82561 | Y25: 0.71719 | Z25: 0.86573 | AA25: 0.84894 | AB25: 0.80556 | AC25: 0.69208 | AD25: 19 | AE25: 19 | AF25: 0.75026 | AG25: 0.55877 | AH25: 0.19149 | AI25: 23 | AJ25: 0 | AK25: 18 | AL25: 0 | AM25: 0 | AN25: 0 | AO25: 0.94783 | AP25: 0 | AQ25: 1 | AR25: y | AS25: y | AT25: y | AU25: y | AV25: y | AW25: y | AX25: y | AY25: m | AZ25: y | BA25: m | BB25: y | BC25: m | BD25: y | BE25: 4 | BG25: ok, use logfit | BI25: 0 | BL25: 1 | BM25: 1 | BS25: 1 | BT25: 1 | BU25: 0 | BV25: 0 | BW25: 1 | BX25: 1 | BY25: 22 | CG25: 1 | CH25: 1 | CI25: 0 | CJ25: 0 | CK25: 1 | CL25: 1
A26: act_net_4.1Sal_d213_m100 | B26: active mobility | C26: The Netherlands | D26: 4.1 | E26: Knowledge Flows (social networks) | F26: annualised Google search frequency (index 100=monthly max.) | G26: Index 0-100 | H26: b7 | I26: 3.0888 | J26: 0.038321 | K26: 1.8942 | L26: 2011.4 | M26: 1.4227 | N26: 51.304 | O26: 2.0418 | P26: 1941 | Q26: -3780.9 | R26: 0.52841 | S26: 0.44519 | T26: 19.881 | U26: 15.557 | V26: 0.10943 | W26: 0.010474 | X26: 27.321 | Y26: 22.73 | Z26: 0.15696 | AA26: 0.063294 | AB26: 26.582 | AC26: 21.903 | AD26: 21 | AE26: 20 | AF26: 1.9492 | AG26: 0.061706 | AH26: 1.8875 | AI26: 21 | AJ26: 8 | AK26: 17 | AL26: 1 | AM26: 1 | AN26: 1 | AO26: 0.93508 | AP26: 0 | AQ26: 1 | AR26: m | AS26: y | AT26: y | AU26: y | AV26: y | AW26: y | AX26: y | AY26: y | AZ26: m | BA26: m | BB26: m | BC26: m | BD26: m | BI26: 0 | BJ26: hide | BK26: original | BL26: 1 | BM26: 1 | BN26: 0 | BO26: 0 | BP26: 0 | BQ26: 0 | BS26: 1 | BT26: 0 | BU26: 0 | BV26: 0 | BW26: 0 | BX26: 0 | BY26: 23 | CA26: check | CG26: 1 | CH26: 1 | CI26: 0 | CJ26: 0 | CK26: 0 | CL26: 0
A27: act_net_4.1Sal_d239_m153 | B27: active mobility | C27: The Netherlands | D27: 4.1 | E27: Knowledge Flows (social networks) | F27: Partial up to max annualised Google search frequency (index 100=monthly max.) | G27: Partial up to max Index 0-100 | H27: b7 | I27: 1.1394 | J27: 0.28364 | K27: 8.1967 | L27: 2012.4 | M27: 3.8569 | N27: 96.414 | O27: 0.012954 | P27: 1984 | Q27: -16442 | R27: 0.96663 | S27: 0.95551 | T27: 6.5285 | U27: 5.043 | V27: 0.89473 | W27: 0.87368 | X27: 11.596 | Y27: 10.341 | Z27: 0.73634 | AA27: 0.68361 | AB27: 18.352 | AC27: 16.877 | AD27: 13 | AE27: 12 | AF27: 1.0372 | AG27: 0.032835 | AH27: 1.0044 | AI27: 13 | AJ27: 0 | AK27: 9 | AL27: 0 | AM27: 1 | AN27: 1 | AO27: 0.80207 | AP27: 0 | AQ27: 1 | AR27: y | AS27: y | AT27: y | AU27: m | AV27: y | AW27: m | AX27: y | AY27: y | AZ27: y | BA27: m | BB27: m | BC27: m | BD27: m | BI27: 0 | BJ27: prefer | BK27: transformed-partial | BL27: 1 | BM27: 1 | BN27: 0 | BO27: 0 | BP27: 1 | BQ27: 1 | BS27: 1 | BT27: 1 | BU27: 0 | BV27: 0 | BW27: 1 | BX27: 1 | BY27: 24 | CG27: 1 | CH27: 1 | CI27: 0 | CJ27: 0 | CK27: 1 | CL27: 1
A28: cli_ban_1.1Ado_d072_m017 | B28: climate protest | C28: Bangladesh | D28: 1.1 | E28: Adoption over Time | F28: Count of participants at protest events related to climate | G28: # people (estimated) | H28: s3 | I28: 41.944 | J28: 0.089972 | K28: 18.132 | L28: 2018.2 | M28: 0.10477 | N28: 290 | O28: 0.023617 | P28: 1923.1 | Q28: -36460 | R28: 0.19742 | S28: -0.07011 | T28: 284.47 | U28: 140 | V28: 0.026697 | W28: -0.16796 | X28: 313.27 | Y28: 169.47 | Z28: 0.045649 | AA28: -0.14522 | AB28: 310.2 | AC28: 161.88 | AD28: 13 | AE28: 3 | AF28: 4.1379 | AG28: 0.34483 | AH28: 3.7931 | AI28: 3 | AJ28: 2 | AK28: 1 | AL28: 0 | AM28: 1 | AN28: 1 | AO28: 0.091681 | AP28: 0 | AQ28: 0 | AR28: n | AS28: n | AT28: y | AU28: y | AV28: y | AW28: y | AX28: m | AY28: y | AZ28: m | BA28: n | BB28: n | BC28: n | BD28: n | BE28: 4 | BG28: convert to cum | BI28: 0 | BJ28: hide | BK28: original | BL28: 0 | BM28: 1 | BN28: 0 | BO28: 0 | BP28: 0 | BQ28: 0 | BS28: 0 | BT28: 0 | BU28: 0 | BV28: 0 | BW28: 0 | BX28: 0 | BY28: 25 | CA28: check | CG28: 0 | CH28: 1 | CI28: 0 | CJ28: 0 | CK28: 0 | CL28: 0
A29: cli_ban_1.1Ado_d073_m019 | B29: climate protest | C29: Bangladesh | D29: 1.1 | E29: Adoption over Time | F29: Count of protest events related to climate | G29: # protest events | H29: s3 | I29: 30.435 | J29: 0.12799 | K29: 1.8187 | L29: 2018.3 | M29: 0.14439 | N29: 23.8 | O29: 9.1992 | P29: 2017.2 | Q29: -3658.9 | R29: 0.45368 | S29: 0.27158 | T29: 12.502 | U29: 6.1386 | V29: 0.11556 | W29: -0.061327 | X29: 15.907 | Y29: 10.359 | Z29: 0.16186 | AA29: -0.0057636 | AB29: 15.485 | AC29: 9.6932 | AD29: 13 | AE29: 6 | AF29: 2.605 | AG29: 0.12605 | AH29: 2.479 | AI29: 13 | AJ29: 4 | AK29: 12 | AL29: 1 | AM29: 0 | AN29: 1 | AO29: 0.43956 | AP29: 0 | AQ29: 1 | AR29: m | AS29: y | AT29: y | AU29: m | AV29: m | AW29: m | AX29: m | AY29: y | AZ29: m | BA29: m | BB29: m | BC29: n | BD29: m | BE29: 4 | BG29: convert to cum | BI29: 0 | BJ29: hide | BK29: original | BL29: 0 | BM29: 1 | BN29: 0 | BO29: 0 | BP29: 0 | BQ29: 0 | BS29: 0 | BT29: 0 | BU29: 0 | BV29: 0 | BW29: 0 | BX29: 0 | BY29: 26 | CA29: check | CG29: 0 | CH29: 1 | CI29: 0 | CJ29: 0 | CK29: 0 | CL29: 0
A30: cli_ban_1.1Ado_d240_m154 | B30: climate protest | C30: Bangladesh | D30: 1.1 | E30: Adoption over Time | F30: cumulative Count of participants at protest events related to climate | G30: cumulative # people (estimated) | H30: s3 | I30: 7.7138 | J30: 0.26593 | K30: 154.12 | L30: 2018.8 | M30: 0.56969 | N30: 1412.6 | O30: 1.2771e-07 | P30: 1935.1 | Q30: -310330 | R30: 0.99711 | S30: 0.99614 | T30: 36.015 | U30: 17.574 | V30: 0.76035 | W30: 0.71241 | X30: 327.78 | Y30: 282.62 | Z30: 0.74177 | AA30: 0.69012 | AB30: 340.25 | AC30: 287.02 | AD30: 13 | AE30: 5 | AF30: 1.0265 | AG30: 0.84952 | AH30: 0.17698 | AI30: 5 | AJ30: 2 | AK30: 4 | AL30: 1 | AM30: 0 | AN30: 0 | AO30: 0.8106 | AP30: 0 | AQ30: 0 | AR30: y | AS30: n | AT30: y | AU30: y | AV30: y | AW30: y | AX30: y | AY30: m | AZ30: y | BA30: n | BB30: n | BC30: n | BD30: n | BI30: 0 | BK30: transformed-cumulative | BL30: 1 | BM30: 1 | BN30: 0 | BO30: 0 | BP30: 0 | BQ30: 0 | BS30: 1 | BT30: 1 | BU30: 0 | BV30: 1 | BW30: 0 | BX30: 0 | BY30: 27 | CC30: **check** | CG30: 1 | CH30: 1 | CI30: 0 | CJ30: 0 | CK30: 0 | CL30: 0
A31: cli_ban_1.1Ado_d241_m155 | B31: climate protest | C31: Bangladesh | D31: 1.1 | E31: Adoption over Time | F31: cumulative Count of protest events related to climate | G31: cumulative # protest events | H31: s3 | I31: 1.7709 | J31: 0.2891 | K31: 11.418 | L31: 2019.1 | M31: 2.4814 | N31: 115.39 | O31: 0.0021787 | P31: 1984.6 | Q31: -22989 | R31: 0.98523 | S31: 0.9803 | T31: 5.9341 | U31: 4.8395 | V31: 0.8599 | W31: 0.83188 | X31: 18.274 | Y31: 15.554 | Z31: 0.76568 | AA31: 0.71882 | AB31: 23.633 | AC31: 19.856 | AD31: 13 | AE31: 13 | AF31: 1.0572 | AG31: 0.025998 | AH31: 1.0312 | AI31: 13 | AJ31: 0 | AK31: 12 | AL31: 0 | AM31: 0 | AN31: 1 | AO31: 0.81021 | AP31: 0 | AQ31: 0 | AR31: y | AS31: y | AT31: y | AU31: m | AV31: y | AW31: m | AX31: y | AY31: y | AZ31: y | BA31: m | BB31: m | BC31: m | BD31: m | BI31: 0 | BJ31: prefer-absolute | BK31: transformed-cumulative | BL31: 1 | BM31: 1 | BN31: 0 | BO31: 2 | BP31: 0 | BQ31: 0 | BS31: 1 | BT31: 1 | BU31: 0 | BV31: 0 | BW31: 0 | BX31: 0 | BY31: 28 | CG31: 1 | CH31: 1 | CI31: 0 | CJ31: 0 | CK31: 0 | CL31: 0
A32: cli_ban_1.1Ado_d346_m185 | B32: climate protest | C32: Bangladesh | D32: 1.1 | E32: Adoption over Time | F32: cumulative share of population participating in protest events related to climate | G32: market share | H32: s3 | I32: 8.3951 | J32: 0.26242 | K32: 9.1286e-07 | L32: 2018.8 | M32: 0.52345 | N32: 8.3708e-06 | O32: 122.11 | P32: 2084.9 | Q32: -0.0018381 | R32: 0.99793 | S32: 0.99724 | T32: 1.8115e-07 | U32: 8.6081e-08 | V32: 0.7489 | W32: 0.69867 | X32: 1.994e-06 | Y32: 1.7168e-06 | Z32: 0.73674 | AA32: 0.68409 | AB32: 2.0417e-06 | AC32: 1.7336e-06 | AD32: 13 | AE32: 5 | AF32: 1.0332 | AG32: 0.86928 | AH32: 0.1639 | AI32: 5 | AJ32: 2 | AK32: 4 | AL32: 1 | AM32: 0 | AN32: 0 | AO32: 0.81198 | AP32: 1 | AQ32: 1 | AR32: y | AS32: n | AT32: y | AU32: y | AV32: y | AW32: y | AX32: y | AY32: m | AZ32: y | BA32: n | BB32: n | BC32: n | BD32: n | BH32: weird data | BI32: 0 | BJ32: prefer-relative | BK32: transformed-marketshare | BL32: 0 | BM32: 1 | BN32: 0 | BO32: 1 | BP32: 0 | BQ32: 0 | BS32: 1 | BT32: 1 | BU32: 0 | BV32: 0 | BW32: 0 | BX32: 0 | BY32: 29 | BZ32: check | CC32: **check** | CG32: 1 | CH32: 1 | CI32: 0 | CJ32: 1 | CK32: 0 | CL32: 0
A33: cli_ban_4.1Sal_d213_m100 | B33: climate protest | C33: Bangladesh | D33: 4.1 | E33: Knowledge Flows (social networks) | F33: annualised Google search frequency (index 100=monthly max.) | G33: Index 0-100 | H33: s3 | I33: -38.414 | J33: -0.060495 | K33: -0.64935 | L33: 2009.8 | M33: -0.1144 | N33: 16.667 | O33: -1523.3 | P33: -154770 | Q33: 1312.6 | R33: 0.125 | S33: -0.029412 | T33: 19.92 | U33: 7.9366 | V33: -0.05 | W33: -0.16667 | X33: 21.822 | Y33: 4.7619 | Z33: 0.034091 | AA33: -0.073232 | AB33: 20.93 | AC33: 9.0703 | AD33: 21 | AE33: 1 | AF33: 6 | AG33: 6 | AH33: 0 | AI33: 1 | AJ33: 0 | AK33: 0 | AL33: 0 | AM33: 0 | AP33: 0 | AQ33: 1 | AR33: n | AS33: n | AT33: m | AU33: m | AV33: m | AW33: m | AX33: m | AY33: m | AZ33: m | BA33: n | BB33: n | BC33: n | BD33: n | BH33: too few | BI33: 0 | BJ33: hide | BK33: original | BL33: 0 | BM33: 0 | BN33: 0 | BO33: 0 | BP33: 0 | BQ33: 0 | BS33: 0 | BT33: 0 | BU33: 0 | BV33: 0 | BW33: 0 | BX33: 0 | BY33: 30 | CG33: 0 | CH33: 0 | CI33: 0 | CJ33: 0 | CK33: 0 | CL33: 0
A34: cli_ban_4.1Sal_d239_m153 | B34: climate protest | C34: Bangladesh | D34: 4.1 | E34: Knowledge Flows (social networks) | F34: Partial up to max annualised Google search frequency (index 100=monthly max.) | G34: Partial up to max Index 0-100 | H34: s3 | I34: 17.735 | K34: 14.286 | L34: 2009 | M34: 0.24779 | N34: 220.71 | Q34: -28648 | R34: 1 | S34: 1 | T34: 1.4826e-06 | U34: 6.1813e-07 | Z34: 0.42857 | AA34: 0.047619 | AB34: 28.172 | AC34: 23.81 | AD34: 6 | AE34: 1 | AF34: 0.45308 | AG34: 0.45308 | AH34: 0 | AI34: 1 | AJ34: 0 | AK34: 0 | AL34: 0 | AM34: 0 | AP34: 0 | AQ34: 1 | AR34: y | AS34: n | AT34: y | AU34: m | AV34: m | AW34: m | AX34: m | AY34: m | AZ34: y | BA34: n | BB34: n | BC34: n | BD34: n | BH34: too few | BI34: 0 | BJ34: prefer | BK34: transformed-partial | BL34: 0 | BM34: 0 | BN34: 0 | BO34: 0 | BP34: 0 | BQ34: 1 | BS34: 0 | BT34: 0 | BU34: 0 | BV34: 0 | BW34: 0 | BX34: 1 | BY34: 31 | CG34: 0 | CH34: 0 | CI34: 0 | CJ34: 0 | CK34: 0 | CL34: 1
A35: cli_ger_1.1Ado_d072_m017 | B35: climate protest | C35: Germany | D35: 1.1 | E35: Adoption over Time | F35: Count of participants at protest events related to climate | G35: # people (estimated) | H35: s3 | I35: 22.928 | J35: 0.20014 | K35: 45.856 | L35: 2020 | M35: 0.19167 | N35: 570.82 | O35: 0.00038393 | P35: 1953 | Q35: -92329 | R35: 0.36992 | S35: 0.1599 | T35: 322.67 | U35: 146.14 | V35: 0.14896 | W35: -0.021243 | X35: 375 | Y35: 229.31 | Z35: 0.17816 | AA35: 0.013788 | AB35: 368.51 | AC35: 227.02 | AD35: 13 | AE35: 4 | AF35: 2.6641 | AG35: 0.15783 | AH35: 2.5063 | AI35: 4 | AJ35: 2 | AK35: 1 | AL35: 1 | AM35: 1 | AN35: 1 | AO35: 0.30332 | AP35: 0 | AQ35: 0 | AR35: m | AS35: n | AT35: y | AU35: y | AV35: m | AW35: m | AX35: m | AY35: y | AZ35: m | BA35: n | BB35: n | BC35: n | BD35: n | BE35: 4 | BG35: convert to cum | BI35: 0 | BJ35: hide | BK35: original | BL35: 0 | BM35: 1 | BN35: 0 | BO35: 0 | BP35: 0 | BQ35: 0 | BS35: 0 | BT35: 1 | BU35: 0 | BV35: 0 | BW35: 0 | BX35: 0 | BY35: 32 | CG35: 0 | CH35: 1 | CI35: 0 | CJ35: 0 | CK35: 0 | CL35: 0
A36: cli_ger_1.1Ado_d073_m019 | B36: climate protest | C36: Germany | D36: 1.1 | E36: Adoption over Time | F36: Count of protest events related to climate | G36: # protest events | H36: s3 | I36: 0.5546 | J36: 0.51177 | K36: 54.467 | L36: 2026 | M36: 7.9237 | N36: 5215.2 | O36: 3.6135e-08 | P36: 1976.3 | Q36: -109700 | R36: 0.92641 | S36: 0.90188 | T36: 71.314 | U36: 50.781 | V36: 0.92613 | W36: 0.91136 | X36: 71.446 | Y36: 51.438 | Z36: 0.601 | AA36: 0.5212 | AB36: 166.05 | AC36: 124.63 | AD36: 13 | AE36: 4 | AF36: 0.16854 | AG36: 0.062126 | AH36: 0.10642 | AI36: 4 | AJ36: 0 | AK36: 3 | AL36: 0 | AM36: 0 | AN36: 1 | AO36: 0.53716 | AP36: 0 | AQ36: 0 | AR36: y | AS36: n | AT36: y | AU36: y | AV36: y | AW36: y | AX36: m | AY36: m | AZ36: y | BA36: n | BB36: n | BC36: n | BD36: n | BE36: 1 | BI36: 0 | BJ36: hide | BK36: original | BL36: 0 | BM36: 1 | BN36: 0 | BO36: 0 | BP36: 0 | BQ36: 0 | BS36: 1 | BT36: 1 | BU36: 0 | BV36: 0 | BW36: 0 | BX36: 0 | BY36: 33 | BZ36: check | CG36: 1 | CH36: 1 | CI36: 0 | CJ36: 0 | CK36: 0 | CL36: 0
A37: cli_ger_1.1Ado_d240_m154 | B37: climate protest | C37: Germany | D37: 1.1 | E37: Adoption over Time | F37: cumulative Count of participants at protest events related to climate | G37: cumulative # people (estimated) | H37: s3 | I37: 4.0104 | J37: 0.42036 | K37: 173.78 | L37: 2020.4 | M37: 1.0958 | N37: 2064.6 | O37: 4.5604e-10 | P37: 1953.2 | Q37: -350010 | R37: 0.99946 | S37: 0.99928 | T37: 19.559 | U37: 8.4271 | V37: 0.83947 | W37: 0.80737 | X37: 336.47 | Y37: 247.98 | Z37: 0.59945 | AA37: 0.51934 | AB37: 531.5 | AC37: 476.34 | AD37: 13 | AE37: 4 | AF37: 1.0236 | AG37: 0.19417 | AH37: 0.82942 | AI37: 4 | AJ37: 0 | AK37: 3 | AL37: 0 | AM37: 0 | AN37: 1 | AO37: 0.71867 | AP37: 0 | AQ37: 0 | AR37: y | AS37: n | AT37: y | AU37: y | AV37: y | AW37: y | AX37: y | AY37: y | AZ37: y | BA37: n | BB37: n | BC37: n | BD37: n | BI37: 0 | BK37: transformed-cumulative | BL37: 1 | BM37: 1 | BN37: 0 | BO37: 0 | BP37: 0 | BQ37: 0 | BS37: 1 | BT37: 1 | BU37: 0 | BV37: 1 | BW37: 0 | BX37: 0 | BY37: 34 | CC37: **check** | CG37: 1 | CH37: 1 | CI37: 0 | CJ37: 0 | CK37: 0 | CL37: 0
A38: cli_ger_1.1Ado_d241_m155 | B38: climate protest | C38: Germany | D38: 1.1 | E38: Adoption over Time | F38: cumulative Count of protest events related to climate | G38: cumulative # protest events | H38: s3 | I38: 0.88528 | J38: 0.6116 | K38: 119.76 | L38: 2022.7 | M38: 4.9639 | N38: 3601.9 | O38: 8.3646e-12 | P38: 1968.8 | Q38: -241230 | R38: 0.99123 | S38: 0.98831 | T38: 56.143 | U38: 36.018 | V38: 0.98566 | W38: 0.98279 | X38: 71.805 | Y38: 45.767 | Z38: 0.55863 | AA38: 0.47035 | AB38: 398.3 | AC38: 314.95 | AD38: 13 | AE38: 4 | AF38: 0.56109 | AG38: 0.089951 | AH38: 0.47113 | AI38: 4 | AJ38: 0 | AK38: 3 | AL38: 0 | AM38: 0 | AN38: 1 | AO38: 0.56235 | AP38: 0 | AQ38: 0 | AR38: y | AS38: n | AT38: y | AU38: y | AV38: y | AW38: y | AX38: m | AY38: y | AZ38: y | BA38: n | BB38: n | BC38: n | BD38: n | BI38: 0 | BJ38: prefer-absolute | BK38: transformed-cumulative | BL38: 1 | BM38: 1 | BN38: 0 | BO38: 2 | BP38: 0 | BQ38: 0 | BS38: 1 | BT38: 1 | BU38: 0 | BV38: 0 | BW38: 0 | BX38: 0 | BY38: 35 | CG38: 1 | CH38: 1 | CI38: 0 | CJ38: 0 | CK38: 0 | CL38: 0
A39: cli_ger_1.1Ado_d346_m185 | B39: climate protest | C39: Germany | D39: 1.1 | E39: Adoption over Time | F39: cumulative share of population participating in protest events related to climate | G39: market share | H39: s3 | I39: 4.1188 | J39: 0.4186 | K39: 2.0649e-06 | L39: 2020.3 | M39: 1.0669 | N39: 2.4479e-05 | O39: 6.8771 | P39: 2052.5 | Q39: -0.004159 | R39: 0.99957 | S39: 0.99943 | T39: 2.0681e-07 | U39: 8.9035e-08 | V39: 0.83679 | W39: 0.80415 | X39: 4.0322e-06 | Y39: 2.9704e-06 | Z39: 0.59922 | AA39: 0.51906 | AB39: 6.3186e-06 | AC39: 5.6597e-06 | AD39: 13 | AE39: 4 | AF39: 1.0211 | AG39: 0.19582 | AH39: 0.82527 | AI39: 4 | AJ39: 0 | AK39: 3 | AL39: 0 | AM39: 0 | AN39: 1 | AO39: 0.71961 | AP39: 1 | AQ39: 1 | AR39: y | AS39: n | AT39: y | AU39: y | AV39: y | AW39: y | AX39: y | AY39: y | AZ39: y | BA39: n | BB39: n | BC39: n | BD39: n | BH39: weird data | BI39: 0 | BJ39: prefer-relative | BK39: transformed-marketshare | BL39: 0 | BM39: 1 | BN39: 0 | BO39: 1 | BP39: 0 | BQ39: 0 | BS39: 1 | BT39: 1 | BU39: 0 | BV39: 0 | BW39: 0 | BX39: 0 | BY39: 36 | BZ39: check | CC39: **check** | CG39: 1 | CH39: 1 | CI39: 0 | CJ39: 1 | CK39: 0 | CL39: 0
A40: cli_ger_4.1Sal_d213_m100 | B40: climate protest | C40: Germany | D40: 4.1 | E40: Knowledge Flows (social networks) | F40: annualised Google search frequency (index 100=monthly max.) | G40: Index 0-100 | H40: s3 | I40: 40.641 | J40: 0.51165 | K40: 1.778 | L40: 2022.3 | M40: 0.10813 | N40: 73.455 | O40: 6.8564 | P40: 2019.5 | Q40: -3574 | R40: 0.87386 | S40: 0.8516 | T40: 8.1921 | U40: 2.5282 | V40: 0.56273 | W40: 0.51414 | X40: 15.253 | Y40: 6.7587 | Z40: 0.21788 | AA40: 0.13098 | AB40: 20.399 | AC40: 13.075 | AD40: 21 | AE40: 2 | AF40: 1.3614 | AG40: 0.63861 | AH40: 0.72277 | AI40: 2 | AJ40: 1 | AK40: 0 | AL40: 0 | AM40: 0 | AN40: 1 | AO40: 0.38449 | AP40: 0 | AQ40: 1 | AR40: y | AS40: n | AT40: m | AU40: y | AV40: y | AW40: y | AX40: m | AY40: y | AZ40: m | BA40: n | BB40: n | BC40: n | BD40: n | BI40: 0 | BJ40: hide | BK40: original | BL40: 1 | BM40: 1 | BN40: 0 | BO40: 0 | BP40: 0 | BQ40: 0 | BS40: 1 | BT40: 1 | BU40: 0 | BV40: 0 | BW40: 0 | BX40: 0 | BY40: 37 | CG40: 1 | CH40: 1 | CI40: 0 | CJ40: 0 | CK40: 0 | CL40: 0
...

Sheet summary_table_v26_23SIs
A1: Code | B1: Innovation Name | C1: Spatial Scale | D1: Indicator Number | E1: Indicator Name | F1: Description | G1: Metric | H1: Category | I1: slope_log | J1: slope_exp | K1: slope_lin | L1: log_t0 | M1: log_Dt | N1: log_K | O1: exp_a | P1: exp_c | Q1: lin_intercept | R1: log_r2 | S1: log_r2adj | T1: log_rmse | U1: log_mae | V1: exp_r2 | W1: exp_r2adj | X1: exp_rmse | Y1: exp_mae | Z1: lin_r2 | AA1: lin_r2adj | AB1: lin_rmse | AC1: lin_mae | AD1: n_data_points | AE1: n_non_zero_data_points | AF1: max_over_K | AG1: min_over_K | AH1: range_over_k | AI1: length_trimmed_series_years | AJ1: n_data_points_beyond_max | AK1: n_data_points_beyond_min | AL1: suspected_reversal_up2down | AM1: suspected_reversal_down2up | AN1: at_least_one_big_jump | AO1: autocorr_l1 | AP1: all_values_less_than_or_equal_to_1 | AQ1: all_values_less_than_or_equal_to_100 | AR1: C1_R2 | AS1: C2_threshold_non_zero_value_years | AT1: C3_pct_non_zero | AU1: C4_less_than_250_jump_in_second_half | AV1: C4_less_than_80_fall_in_second_half | AW1: C4_combined_less_than_80_fall_and_250_jump_in_second_half | AX1: C5_volatility_autocorrelation_lag1_threshold_0.7 | AY1: C6_{K_COVERAGE_THRESHOLD}_of_k_covered_by_data | AZ1: C7_lin_r2 | BA1: use_log_x | BB1: use_lin_x | BC1: use_log_y | BD1: use_lin_y | BE1: old GN scoring @retreat | BF1: old GN comments | BG1: old CW scoring @retreat | BH1: comments_fit_CW | BI1: comments_delete_CW | BJ1: comments_alternativeseries_CW | BK1: comments_transformations_CW | BL1: use_logfit_CW | BM1: use_linfit_CW | BN1: select_1.1_earegion_CW | BO1: select_1.1_allregions_CW | BP1: select_non1.1s_earegion_CW | BQ1: select_non1.1s_allregions_CW | BR1: GN final scoring | BS1: use_logfit_GN | BT1: use_linfit_GN | BU1: select_1.1_earegion_GN | BV1: select_1.1_allregions_GN | BW1: select_non1.1s_earegion_GN | BX1: select_non1.1s_allregions_GN | BY1: PDF page | BZ1: use_logfit_AGREE? | CA1: use_linfit_AGREE? | CB1: select_1.1_earegion_AGREE? | CC1: select_1.1_allregions_AGREE? | CD1: select_non1.1s_earegion_AGREE? | CE1: select_non1.1s_allregions_AGREE? | CF1: FINAL_AGREED | CG1: use_logfit_FIN | CH1: use_linfit_FIN | CI1: select_1.1_earegion_FIN | CJ1: select_1.1_allregions_FIN | CK1: select_non1.1s_earegion_FIN | CL1: select_non1.1s_allregions_FIN | CM1: CWnotes_6May | CN1: GN notes 9 may
A2: act_ams_1.1Ado_d063_m028 | B2: active mobility | C2: Amsterdam | D2: 1.1 | E2: Adoption over time | F2: Bike ownership | G2: % | H2: b7 | I2: 6.1161 | J2: 0.0054776 | K2: 0.0038502 | L2: 1984.7 | M2: 0.7185 | N2: 0.71167 | O2: 0.76729 | P2: 2018.3 | Q2: -7.0056 | R2: 0.67402 | S2: 0.34804 | T2: 0.022307 | U2: 0.018571 | V2: 0.78529 | W2: 0.67794 | X2: 0.018104 | Y2: 0.017715 | Z2: 0.79629 | AA2: 0.69443 | AB2: 0.017635 | AC2: 0.017232 | AD2: 7 | AE2: 7 | AF2: 1.0539 | AG2: 0.87119 | AH2: 0.18267 | AI2: 29 | AJ2: 1 | AK2: 6 | AL2: 0 | AM2: 0 | AN2: 0 | AO2: 0.86693 | AP2: 1 | AQ2: 1 | AR2: m | AS2: y | AT2: y | AU2: y | AV2: y | AW2: y | AX2: y | AY2: m | AZ2: y | BA2: m | BB2: y | BC2: n | BD2: y | BE2: 1 | BI2: 0 | BL2: 0 | BM2: 1 | BN2: 0 | BO2: 0 | BP2: 0 | BQ2: 0 | BS2: 0 | BT2: 1 | BU2: 0 | BV2: 0 | BW2: 0 | BX2: 0 | BY2: 1 | CG2: 0 | CH2: 1 | CI2: 0 | CJ2: 0 | CK2: 0 | CL2: 0 | CO2: means I've changed 0 to 1 or vice versa
A3: act_ams_1.1Ado_d121_m090 | B3: active mobility | C3: Amsterdam | D3: 1.1 | E3: Adoption over time | F3: Modal share of all trips by residents (bike) | G3: % trips by bike | H3: b7 | I3: -0.0023618 | J3: -0.0023613 | K3: -0.00056291 | L3: -1564.6 | M3: -1860.6 | N3: 1091.8 | O3: 0.67031 | P3: 1566.4 | Q3: 1.3672 | R3: 0.17886 | S3: -0.31382 | T3: 0.03044 | U3: 0.027427 | V3: 0.17886 | W3: -0.094847 | X3: 0.03044 | Y3: 0.027427 | Z3: 0.16499 | AA3: -0.11334 | AB3: 0.030696 | AC3: 0.027808 | AD3: 9 | AE3: 9 | AF3: 0.00028395 | AG3: 0.00018319 | AH3: 0.00010076 | AI3: 84 | AJ3: 8 | AK3: 2 | AL3: 0 | AM3: 0 | AN3: 0 | AO3: 0.84023 | AP3: 1 | AQ3: 1 | AR3: n | AS3: y | AT3: y | AU3: y | AV3: y | AW3: y | AX3: y | AY3: m | AZ3: m | BA3: n | BB3: m | BC3: n | BD3: m | BE3: 2 | BI3: 0 | BL3: 1 | BM3: 1 | BN3: 0 | BO3: 0 | BP3: 0 | BQ3: 0 | BS3: 1 | BT3: 1 | BU3: 0 | BV3: 0 | BW3: 0 | BX3: 0 | BY3: 2 | CG3: 1 | CH3: 1 | CI3: 0 | CJ3: 0 | CK3: 0 | CL3: 0 | CO3: means problem, dicuss with GN
A4: act_ams_1.1Ado_d122_m091 | B4: active mobility | C4: Amsterdam | D4: 1.1 | E4: Adoption over time | F4: Modal share of all trips by residents (walk) | G4: % trips by walking | H4: b7 | I4: -16.742 | J4: -0.0042167 | K4: -0.0010874 | L4: 1996.2 | M4: -0.26248 | N4: 0.272 | O4: 0.083316 | P4: 2247.9 | Q4: 2.4124 | R4: -4.8878 | S4: -8.4205 | T4: 0.16055 | U4: 0.13267 | V4: 0.1654 | W4: -0.1128 | X4: 0.060446 | Y4: 0.045681 | Z4: 0.15869 | AA4: -0.12175 | AB4: 0.060688 | AC4: 0.045795 | AD4: 9 | AE4: 9 | AF4: 1.2868 | AG4: 0.44118 | AH4: 0.84559 | AI4: 84 | AJ4: 8 | AK4: 7 | AL4: 0 | AM4: 1 | AN4: 1 | AO4: 0.78584 | AP4: 1 | AQ4: 1 | AR4: n | AS4: y | AT4: y | AU4: y | AV4: y | AW4: y | AX4: y | AY4: y | AZ4: m | BA4: n | BB4: m | BC4: n | BD4: m | BE4: 4 | BG4: ok, use logfit | BI4: 0 | BL4: 1 | BM4: 1 | BN4: 0 | BO4: 0 | BP4: 0 | BQ4: 0 | BS4: 1 | BT4: 1 | BU4: 0 | BV4: 0 | BW4: 0 | BX4: 0 | BY4: 3 | CG4: 0 | CH4: 1 | CI4: 0 | CJ4: 0 | CK4: 0 | CL4: 0 | CM4: SdS: fit partial from 1979 (drop 1930 peak year) | CO4: means new coding for changed indicators post Feb
A5: act_ams_1.1Ado_d332_m185 | B5: active mobility | C5: Amsterdam | D5: 1.1 | E5: Adoption over time | F5: % trips by walking and biking | G5: market share | H5: b7 | I5: -0.0087911 | J5: -0.0033221 | K5: -0.0016503 | L5: 2033.8 | M5: -499.87 | N5: 0.83407 | O5: 0.0026073 | P5: 3568.5 | Q5: 3.7796 | R5: 0.19777 | S5: -0.28356 | T5: 0.078513 | U5: 0.059173 | V5: 0.22115 | W5: -0.038465 | X5: 0.07736 | Y5: 0.058997 | Z5: 0.20825 | AA5: -0.055671 | AB5: 0.077999 | AC5: 0.059339 | AD5: 9 | AE5: 9 | AF5: 0.79131 | AG5: 0.40764 | AH5: 0.38366 | AI5: 84 | AJ5: 8 | AK5: 7 | AL5: 0 | AM5: 1 | AN5: 0 | AO5: 0.82455 | AP5: 1 | AQ5: 1 | AR5: n | AS5: y | AT5: y | AU5: y | AV5: y | AW5: y | AX5: y | AY5: y | AZ5: m | BA5: n | BB5: m | BC5: n | BD5: m | BI5: 0 | BJ5: prefer-relative | BK5: transformed-marketshare | BL5: 1 | BM5: 1 | BN5: 0 | BO5: 1 | BP5: 0 | BQ5: 0 | BS5: 1 | BT5: 1 | BU5: 0 | BV5: 1 | BW5: 0 | BX5: 0 | BY5: 4 | CG5: 1 | CH5: 1 | CI5: 0 | CJ5: 0 | CK5: 0 | CL5: 0 | CO5: means didn't survive _v24 to _v25 transfer
A6: act_ams_1.1Ado_d359_m091 | B6: active mobility | C6: Amsterdam | D6: 1.1 | E6: Adoption over time | F6: Modal share of all trips by residents (walk) EXCLUDING 1930 | G6: % trips by walking | H6: b7 | I6: 1.9434 | J6: 0.0020703 | K6: 0.00060028 | L6: 1970.1 | M6: 2.2612 | N6: 0.25429 | O6: 0.068688 | P6: 1396.9 | Q6: -0.96066 | R6: 0.56052 | S6: 0.23091 | T6: 0.039325 | U6: 0.033214 | V6: 0.014739 | W6: -0.37937 | X6: 0.05888 | Y6: 0.051788 | Z6: 0.018126 | AA6: -0.37462 | AB6: 0.058779 | AC6: 0.052101 | AD6: 8 | AE6: 8 | AF6: 1.2191 | AG6: 0.47191 | AH6: 0.74719 | AI6: 44 | AJ6: 6 | AK6: 7 | AL6: 1 | AM6: 0 | AN6: 1 | AO6: 0.89904 | AP6: 1 | AQ6: 1 | AR6: m | AS6: y | AT6: y | AU6: y | AV6: y | AW6: y | AX6: y | AY6: y | AZ6: m | BA6: m | BB6: m | CG6: 0 | CH6: 1 | CI6: 0 | CJ6: 0 | CK6: 0 | CL6: 0
A7: act_ams_1.1Ado_d360_m185 | B7: active mobility | C7: Amsterdam | D7: 1.1 | E7: Adoption over time | F7: % trips by walking and biking EXCLUDING 1930 | G7: market share | H7: b7 | I7: 1.0857 | J7: 0.0026517 | K7: 0.0013983 | L7: 1969.3 | M7: 4.0475 | N7: 0.49714 | O7: 0.10663 | P7: 1430.8 | Q7: -2.3135 | R7: 0.54632 | S7: 0.20607 | T7: 0.047359 | U7: 0.036072 | V7: 0.062786 | W7: -0.3121 | X7: 0.068069 | Y7: 0.06083 | Z7: 0.070004 | AA7: -0.30199 | AB7: 0.067806 | AC7: 0.060625 | AD7: 8 | AE7: 8 | AF7: 1.1264 | AG7: 0.68391 | AH7: 0.44253 | AI7: 44 | AJ7: 4 | AK7: 7 | AL7: 1 | AM7: 0 | AN7: 0 | AO7: 0.89687 | AP7: 1 | AQ7: 1 | AR7: m | AS7: y | AT7: y | AU7: y | AV7: y | AW7: y | AX7: y | AY7: y | AZ7: m | BA7: m | BB7: m | CG7: 1 | CH7: 1 | CI7: 0 | CJ7: 1 | CK7: 0 | CL7: 0
A8: act_bei_1.1Ado_d060_m028 | B8: active mobility | C8: Beijing | D8: 1.1 | E8: Adoption over time | F8: Bicycle modal share | G8: % | H8: b7 | I8: -128.93 | J8: -0.00040147 | K8: -0.01425 | L8: 1999.7 | M8: -0.034083 | N8: 0.5403 | O8: -1544.5 | P8: -152600 | Q8: 28.852 | R8: -3.1777 | S8: 9.3553 | T8: 0.25892 | U8: 0.205 | V8: -9.2413 | W8: =-inf -> #NAME? | X8: 0.4054 | Y8: 0.3851 | Z8: 0.96449 | AA8: =-inf -> #NAME? | AB8: 0.023871 | AC8: 0.0221 | AD8: 3 | AE8: 3 | AF8: 1 | AG8: 0.42569 | AH8: 0.57431 | AI8: 22 | AJ8: 2 | AK8: 0 | AL8: 0 | AM8: 0 | AN8: 0 | AO8: 0.60149 | AP8: 1 | AQ8: 1 | AR8: n | AS8: m | AT8: y | AU8: y | AV8: y | AW8: y | AX8: m | AY8: y | AZ8: y | BA8: n | BB8: m | BC8: m | BD8: m | BE8: 2 | BI8: 0 | BL8: 1 | BM8: 1 | BN8: 0 | BO8: 0 | BP8: 0 | BQ8: 0 | BS8: 1 | BT8: 1 | BU8: 0 | BV8: 0 | BW8: 0 | BX8: 0 | BY8: 5 | CG8: 0 | CH8: 1 | CI8: 0 | CJ8: 0 | CK8: 0 | CL8: 0
A9: act_bei_1.1Ado_d332_m185 | B9: active mobility | C9: Beijing | D9: 1.1 | E9: Adoption over time | F9: % trips by walking and biking | G9: market share | H9: b7 | I9: -128.93 | J9: -0.00040147 | K9: -0.01425 | L9: 1999.7 | M9: -0.034083 | N9: 0.5403 | O9: -1544.5 | P9: -152600 | Q9: 28.852 | R9: -3.1777 | S9: 9.3553 | T9: 0.25892 | U9: 0.205 | V9: -9.2413 | W9: =-inf -> #NAME? | X9: 0.4054 | Y9: 0.3851 | Z9: 0.96449 | AA9: =-inf -> #NAME? | AB9: 0.023871 | AC9: 0.0221 | AD9: 3 | AE9: 3 | AF9: 1 | AG9: 0.42569 | AH9: 0.57431 | AI9: 22 | AJ9: 2 | AK9: 0 | AL9: 0 | AM9: 0 | AN9: 0 | AO9: 0.60149 | AP9: 1 | AQ9: 1 | AR9: n | AS9: m | AT9: y | AU9: y | AV9: y | AW9: y | AX9: m | AY9: y | AZ9: y | BA9: n | BB9: m | BC9: m | BD9: m | BI9: 0 | BJ9: prefer-relative | BK9: transformed-marketshare | BL9: 1 | BM9: 1 | BN9: 0 | BO9: 1 | BP9: 0 | BQ9: 0 | BS9: 1 | BT9: 1 | BU9: 0 | BV9: 1 | BW9: 0 | BX9: 0 | BY9: 6 | CG9: 0 | CH9: 1 | CI9: 0 | CJ9: 1 | CK9: 0 | CL9: 0
A10: act_chi_1.1Ado_d061_m002 | B10: active mobility | C10: China | D10: 1.1 | E10: Adoption over time | F10: Bicycle ownership | G10: # bikes per hundred households | H10: b7 | I10: 15.465 | J10: 0.020393 | K10: 2.6286 | L10: 1814.4 | M10: 0.28415 | N10: 110.03 | O10: 3.2025 | P10: 1817.7 | Q10: -5121 | R10: 0 | S10: =-inf -> #NAME? | T10: 61.847 | U10: 47.333 | V10: 0.20425 | W10: -1.3873 | X10: 55.17 | Y10: 49.509 | Z10: 0.23213 | AA10: -1.3036 | AB10: 54.195 | AC10: 50.322 | AD10: 4 | AE10: 4 | AF10: 1.7918 | AG10: 0.20794 | AH10: 1.5839 | AI10: 30 | AJ10: 1 | AK10: 2 | AL10: 1 | AM10: 1 | AN10: 1 | AO10: 0.47132 | AP10: 0 | AQ10: 0 | AR10: n | AS10: m | AT10: y | AU10: m | AV10: y | AW10: m | AX10: m | AY10: y | AZ10: m | BA10: n | BB10: m | BC10: m | BD10: m | BE10: 4 | BG10: reject, too few points | BI10: 0 | BL10: 0 | BM10: 1 | BN10: 0 | BO10: 0 | BP10: 0 | BQ10: 0 | BS10: 0 | BT10: 1 | BU10: 0 | BV10: 0 | BW10: 0 | BX10: 0 | BY10: 7 | CG10: 0 | CH10: 1 | CI10: 0 | CJ10: 0 | CK10: 0 | CL10: 0
A11: act_chi_3.2Adc_d062_m003 | B11: active mobility | C11: China | D11: 3.2 | E11: Adopter characteristics | F11: Bicycle ownership among income groups | G11: # bikes per hundred households (highest 10% income) | H11: b7 | I11: -0.25049 | J11: -0.017188 | K11: -3.0744 | L11: 2008 | M11: -17.543 | N11: 187.66 | O11: 280.33 | P11: 1964.3 | Q11: 6300.3 | R11: 0.82934 | S11: =-inf -> #NAME? | T11: 12.667 | U11: 10.677 | V11: 0.51703 | W11: -0.4489 | X11: 21.309 | Y11: 19.229 | Z11: 0.56489 | AA11: -0.30533 | AB11: 20.226 | AC11: 18.246 | AD11: 4 | AE11: 4 | AF11: 1.0823 | AG11: 0.62879 | AH11: 0.45353 | AI11: 21 | AJ11: 2 | AK11: 0 | AL11: 1 | AM11: 0 | AN11: 0 | AO11: 0.78003 | AP11: 0 | AQ11: 0 | AR11: y | AS11: m | AT11: y | AU11: y | AV11: y | AW11: y | AX11: y | AY11: y | AZ11: y | BA11: m | BB11: m | BC11: m | BD11: m | BE11: 2 | BI11: 0 | BL11: 0 | BM11: 1 | BS11: 1 | BT11: 1 | BU11: 0 | BV11: 0 | BW11: 0 | BX11: 0 | BY11: 8 | BZ11: check | CG11: 1 | CH11: 1 | CI11: 0 | CJ11: 0 | CK11: 0 | CL11: 0
A12: act_chi_3.2Adc_d062_m004 | B12: active mobility | C12: China | D12: 3.2 | E12: Adopter characteristics | F12: Bicycle ownership among income groups | G12: # bikes per hundred households (lowest 10% income) | H12: b7 | I12: -2.6167 | J12: -0.0083411 | K12: -1.3736 | L12: 2006.3 | M12: -1.6794 | N12: 157.06 | O12: 227.52 | P12: 1941.8 | Q12: 2886.7 | R12: 0.61758 | S12: =-inf -> #NAME? | T12: 16.895 | U12: 12.122 | V12: 0.12506 | W12: -1.6248 | X12: 25.555 | Y12: 25.04 | Z12: 0.14203 | AA12: -1.5739 | AB12: 25.306 | AC12: 24.861 | AD12: 4 | AE12: 4 | AF12: 1.1498 | AG12: 0.68431 | AH12: 0.46548 | AI12: 21 | AJ12: 2 | AK12: 0 | AL12: 1 | AM12: 0 | AN12: 0 | AO12: 0.80089 | AP12: 0 | AQ12: 0 | AR12: m | AS12: m | AT12: y | AU12: y | AV12: y | AW12: y | AX12: y | AY12: y | AZ12: m | BA12: m | BB12: m | BC12: m | BD12: m | BE12: 2 | BI12: 0 | BL12: 0 | BM12: 1 | BS12: 0 | BT12: 1 | BU12: 0 | BV12: 0 | BW12: 0 | BX12: 0 | BY12: 9 | CG12: 0 | CH12: 1 | CI12: 0 | CJ12: 0 | CK12: 0 | CL12: 0
A13: act_chi_3.2Adc_d062_m005 | B13: active mobility | C13: China | D13: 3.2 | E13: Adopter characteristics | F13: Bicycle ownership among income groups | G13: # bikes per hundred households (middle income groups) | H13: b7 | I13: -0.35805 | J13: -0.013207 | K13: -2.4015 | L13: 2007.8 | M13: -12.273 | N13: 181.57 | O13: 267.65 | P13: 1958.3 | Q13: 4957 | R13: 0.75315 | S13: =-inf -> #NAME? | T13: 14.824 | U13: 11.464 | V13: 0.32729 | W13: -1.0181 | X13: 24.472 | Y13: 23.3 | Z13: 0.364 | AA13: -0.90799 | AB13: 23.795 | AC13: 22.74 | AD13: 4 | AE13: 4 | AF13: 1.1186 | AG13: 0.65538 | AH13: 0.46323 | AI13: 21 | AJ13: 2 | AK13: 0 | AL13: 1 | AM13: 0 | AN13: 0 | AO13: 0.79113 | AP13: 0 | AQ13: 0 | AR13: y | AS13: m | AT13: y | AU13: y | AV13: y | AW13: y | AX13: y | AY13: y | AZ13: y | BA13: m | BB13: m | BC13: m | BD13: m | BE13: 2 | BI13: 0 | BL13: 0 | BM13: 1 | BS13: 1 | BT13: 1 | BU13: 0 | BV13: 0 | BW13: 0 | BX13: 1 | BY13: 10 | BZ13: check | CG13: 1 | CH13: 1 | CI13: 0 | CJ13: 0 | CK13: 0 | CL13: 1
A14: act_chi_4.1Sal_d213_m100 | B14: active mobility | C14: China | D14: 4.1 | E14: Knowledge Flows (social networks) | F14: annualised Google search frequency (index 100=monthly max.) | G14: Index 0-100 | H14: b7 | I14: 2.095 | J14: 0.076912 | K14: 3.6253 | L14: 2013.4 | M14: 2.0976 | N14: 61.747 | O14: 0.65739 | P14: 1963.6 | Q14: -7267.6 | R14: 0.79934 | S14: 0.76393 | T14: 14.129 | U14: 9.9398 | V14: 0.36338 | W14: 0.29265 | X14: 25.166 | Y14: 21.242 | Z14: 0.48439 | AA14: 0.4271 | AB14: 22.649 | AC14: 17.771 | AD14: 21 | AE14: 20 | AF14: 1.6195 | AG14: 0.017461 | AH14: 1.6021 | AI14: 21 | AJ14: 8 | AK14: 20 | AL14: 1 | AM14: 0 | AN14: 1 | AO14: 0.93024 | AP14: 0 | AQ14: 1 | AR14: y | AS14: y | AT14: y | AU14: y | AV14: y | AW14: y | AX14: y | AY14: y | AZ14: y | BA14: y | BB14: y | BC14: y | BD14: y | BI14: 0 | BJ14: hide | BK14: original | BL14: 1 | BM14: 1 | BN14: 0 | BO14: 0 | BP14: 0 | BQ14: 0 | BS14: 1 | BT14: 0 | BU14: 0 | BV14: 0 | BW14: 0 | BX14: 0 | BY14: 11 | CA14: check | CG14: 1 | CH14: 1 | CI14: 0 | CJ14: 0 | CK14: 0 | CL14: 0
A15: act_chi_4.1Sal_d239_m153 | B15: active mobility | C15: China | D15: 4.1 | E15: Knowledge Flows (social networks) | F15: Partial up to max annualised Google search frequency (index 100=monthly max.) | G15: Partial up to max Index 0-100 | H15: b7 | I15: 1.0431 | J15: 0.49369 | K15: 6.5779 | L15: 2014.6 | M15: 4.213 | N15: 123.43 | O15: 0.019473 | P15: 1998.6 | Q15: -13201 | R15: 0.99639 | S15: 0.99519 | T15: 1.8903 | U15: 1.5688 | V15: 0.97515 | W15: 0.97018 | X15: 4.9601 | Y15: 3.8128 | Z15: 0.61177 | AA15: 0.53412 | AB15: 19.606 | AC15: 16.835 | AD15: 13 | AE15: 12 | AF15: 0.81017 | AG15: 0.0087349 | AH15: 0.80143 | AI15: 13 | AJ15: 0 | AK15: 12 | AL15: 0 | AM15: 0 | AN15: 1 | AO15: 0.66032 | AP15: 0 | AQ15: 1 | AR15: y | AS15: y | AT15: y | AU15: y | AV15: y | AW15: y | AX15: m | AY15: y | AZ15: y | BA15: m | BB15: m | BC15: y | BD15: y | BI15: 0 | BJ15: prefer | BK15: transformed-partial | BL15: 1 | BM15: 1 | BN15: 0 | BO15: 0 | BP15: 0 | BQ15: 1 | BS15: 1 | BT15: 1 | BU15: 0 | BV15: 0 | BW15: 0 | BX15: 1 | BY15: 12 | CG15: 1 | CH15: 1 | CI15: 0 | CJ15: 0 | CK15: 0 | CL15: 1
A16: act_cop_1.1Ado_d121_m090 | B16: active mobility | C16: Copenhagen | D16: 1.1 | E16: Adoption over time | F16: Modal share of all trips by residents (bike) | G16: % trips by bike | H16: b7 | I16: 0.014241 | J16: 0.0012979 | K16: 0.0033675 | L16: 2734.2 | M16: 308.58 | N16: 8643.2 | O16: 1555.1 | P16: 157450 | Q16: -6.4834 | R16: 0.784 | S16: =-inf -> #NAME? | T16: 0.018985 | U16: 0.018338 | V16: -38.206 | W16: -116.62 | X16: 0.25578 | Y16: 0.2525 | Z16: 0.7454 | AA16: 0.23619 | AB16: 0.020612 | AC16: 0.020026 | AD16: 4 | AE16: 4 | AF16: 3.7023e-05 | AG16: 2.5454e-05 | AH16: 1.157e-05 | AI16: 28 | AJ16: 0 | AK16: 3 | AL16: 0 | AM16: 0 | AN16: 0 | AO16: 0.7008 | AP16: 1 | AQ16: 1 | AR16: y | AS16: m | AT16: y | AU16: y | AV16: y | AW16: y | AX16: y | AY16: m | AZ16: y | BA16: m | BB16: m | BC16: m | BD16: m | BE16: 2 | BI16: 0 | BL16: 1 | BM16: 1 | BN16: 0 | BO16: 0 | BP16: 0 | BQ16: 0 | BS16: 1 | BT16: 1 | BU16: 0 | BV16: 0 | BW16: 0 | BX16: 0 | BY16: 13 | CG16: 1 | CH16: 1 | CI16: 0 | CJ16: 0 | CK16: 0 | CL16: 0
