Workbook

Sheet Data
A1: SI | B1: co-housing | C1: co-housing | D1: co-housing | E1: co-housing | F1: mobesity | G1: microfinance | H1: microfinance | I1: microfinance | J1: eating less meat | K1: eating less meat | L1: eating less meat | M1: eating less meat | N1: eating less meat | O1: climate protest | P1: climate protest | Q1: climate protest | R1: climate protest | S1: climate protest | T1: climate protest | U1: climate protest | V1: energy community | W1: active mobility | X1: car sharing | Y1: firm ESG reporting | Z1: firm ESG reporting | AA1: firm ESG reporting | AB1: firm ESG reporting | AC1: e-bikes | AD1: e-bikes | AE1: e-bikes | AF1: low carbon long distance travel | AG1: passive building retrofits | AH1: passive building retrofits | AI1: passive building retrofits | AJ1: passive building retrofits
A2: Indicator | B2: Population | C2: Population | D2: Population | E2: Population | F2: heaviest vehicle available | G2: Population | H2: Population | I2: Population | J2: total kg food | K2: total kg food | L2: total kg food | M2: total kg food | N2: total kg food | O2: Population | P2: Population | Q2: Population | R2: Population | S2: Population | T2: Population | U2: Population | V2: Population | W2: pkm- road & rail (millions) | X2: population | Y2: # of firms | Z2: # of firms | AA2: # of firms | AB2: # of firms | AC2: total bike sales | AD2: total bike sales | AE2: total bike sales | AF2: road+rail pkm | AG2: # new renovated houses | AH2: # new renovated houses | AI2: # new renovated houses | AJ2: # new renovated houses
A3: Country | B3: US | C3: Germany | D3: Denmark | E3: Vaud | F3: Germany | G3: India | H3: Bangladesh | I3: Nigeria | J3: Germany | K3: Japan | L3: India | M3: UK | N3: US | O3: Bangladesh | P3: Germany | Q3: India | R3: Sweden | S3: UK | T3: US | U3: Global | V3: The Netherlands | W3: Netherlands | X3: Germany | Y3: Asia-Pacific | Z3: Europe | AA3: Americas | AB3: Middle East & Africa | AC3: China | AD3: Netherlands | AE3: EU | AF3: Germany | AG3: Germany | AH3: Austria | AI3: Belgium | AJ3: Ireland
A4: Source | B4: census.gov | C4: ourworldindata.org | D4: ourworldindata.org | G4: Our World in Data | H4: Our World in Data | I4: Our World in Data | J4: original eating less meat data | K4: original eating less meat data | L4: original eating less meat data | M4: original eating less meat data | N4: original eating less meat data | O4: Our World in Data | P4: Our World in Data | Q4: Our World in Data | R4: Our World in Data | S4: Our World in Data | T4: Our World in Data | U4: Our World in Data | V4: Our World in Data | W4: European Environment Agency | X4: Our World in Data | Y4: globalreporting.org | Z4: globalreporting.org | AA4: globalreporting.org | AB4: globalreporting.org | AC4: Statisa | AD4: Statisa | AE4: Statisa | AF4: Our World in Data | AG4: European Commission Joint Research Centre Data Catalogue | AH4: European Commission Joint Research Centre Data Catalogue | AI4: European Commission Joint Research Centre Data Catalogue | AJ4: European Commission Joint Research Centre Data Catalogue
A5: URL | C5: https://ourworldindata.org/grapher/population-unwpp?country=DNK~DEU~CHE | D5: https://ourworldindata.org/grapher/population-unwpp?country=DNK~DEU~CHE | E5: https://citypopulation.de/en/switzerland/cities/ | G5: https://ourworldindata.org/grapher/population?time=1890..latest&country=IND~BGD~NGA | H5: https://ourworldindata.org/grapher/population?time=1890..latest&country=IND~BGD~NGA | I5: https://ourworldindata.org/grapher/population?time=1890..latest&country=IND~BGD~NGA | O5: https://ourworldindata.org/grapher/population?time=1890..latest&country=IND~BGD~NGA | P5: https://ourworldindata.org/grapher/population-unwpp?country=DNK~DEU~CHE | Q5: https://ourworldindata.org/grapher/population?time=1890..latest&country=IND~BGD~NGA | R5: https://ourworldindata.org/grapher/population?time=1909..latest&country=USA~OWID_WRL~GBR | S5: https://ourworldindata.org/grapher/population?time=1909..latest&country=USA~OWID_WRL~GBR | T5: https://ourworldindata.org/grapher/population?time=1909..latest&country=USA~OWID_WRL~GBR | U5: https://ourworldindata.org/grapher/population?time=1909..latest&country=USA~OWID_WRL~GBR | V5: https://ourworldindata.org/grapher/population?time=1909..latest&country=~NLD | W5: https://www.eea.europa.eu/en/analysis/publications/sustainability-of-europes-mobility-systems/passenger-transport-activity/eu-27-passenger-transport-activity-gpkm-for-different-transport-modes-according-to-the-ff55-mix-scenario?activeTab=570bee2d-1316-48cf-adde-4b640f92119b | Y5: https://www.globalreporting.org/news/news-center/gri-global-adoption-by-top-companies-continues-to-grow/ | Z5: https://www.globalreporting.org/news/news-center/gri-global-adoption-by-top-companies-continues-to-grow/ | AA5: https://www.globalreporting.org/news/news-center/gri-global-adoption-by-top-companies-continues-to-grow/ | AB5: https://www.globalreporting.org/news/news-center/gri-global-adoption-by-top-companies-continues-to-grow/ | AC5: see ebikes sheet for url | AD5: see ebikes sheet for url | AE5: see ebikes sheet for url | AF5: https://ourworldindata.org/grapher/annual-reported-passenger-kilometers?country=~NLD | AG5: https://data.jrc.ec.europa.eu/dataset/82322924-506a-4c9a-8532-2bdd30d69bf5#dataaccess | AH5: https://data.jrc.ec.europa.eu/dataset/82322924-506a-4c9a-8532-2bdd30d69bf5#dataaccess | AI5: https://data.jrc.ec.europa.eu/dataset/82322924-506a-4c9a-8532-2bdd30d69bf5#dataaccess | AJ5: https://data.jrc.ec.europa.eu/dataset/82322924-506a-4c9a-8532-2bdd30d69bf5#dataaccess
A6: units | B6: people | C6: people | D6: people | E6: people | F6: kg | G6: people | H6: people | I6: people | J6: kg food | K6: kg food | L6: kg food | M6: kg food | N6: kg food | O6: people | P6: people | Q6: people | R6: people | S6: people | T6: people | U6: people | V6: people | X6: people | Y6: % | Z6: % | AA6: % | AB6: % | AC6: million | AD6: million | AE6: million | AF6: pkm | AG6: houses | AH6: houses | AI6: houses | AJ6: houses
A7: 1900 | F7: 3129 | R7: 5123503
A8: 1901 | F8: 3129 | R8: 5157047
A9: 1902 | F9: 3129 | R9: 5190268
A10: 1903 | F10: 3129 | R10: 5223160
A11: 1904 | F11: 3129 | R11: 5256260
A12: 1905 | F12: 3129 | R12: 5289570
A13: 1906 | F13: 3129 | R13: 5323091
A14: 1907 | F14: 3129 | R14: 5356825
A15: 1908 | F15: 3129 | R15: 5390772
A16: 1909 | F16: 3129 | R16: 5426317
A17: 1910 | F17: 3129 | R17: 5463482
A18: 1911 | F18: 3129 | R18: 5502286
... A76: 1969 | F76: 3129 | R76: 7968013
A77: 1970 | B77: 203211926 | C77: ='cohousing population'!D96 -> 78205102 | D77: ='cohousing population'!D22 -> 4928676 | F77: 3129 | J77: ='elm- g'!C21 -> 139.03019 | K77: ='elm- j'!C21 -> 142.01987 | L77: ='elm-i'!C21 -> 46.437518 | M77: ='elm- uk'!C21 -> 148.55998 | N77: ='elm- us'!C21 -> 210.22802 | R77: 8042783
A78: 1971 | B78: 202907917 | C78: ='cohousing population'!D97 -> 78345873 | D78: ='cohousing population'!D23 -> 4963062 | F78: 3129 | J78: ='elm- g'!C22 -> 140.8669 | K78: ='elm- j'!C22 -> 147.91391 | L78: ='elm-i'!C22 -> 47.267345 | M78: ='elm- uk'!C22 -> 149.89216 | N78: ='elm- us'!C22 -> 216.43923 | R78: 8098105
A79: 1972 | B79: 205238390 | C79: ='cohousing population'!D98 -> 78719923 | D79: ='cohousing population'!D24 -> 4991568 | F79: 3129 | J79: ='elm- g'!C23 -> 146.15464 | K79: ='elm- j'!C23 -> 149.30463 | L79: ='elm-i'!C23 -> 48.061274 | M79: ='elm- uk'!C23 -> 147.39541 | N79: ='elm- us'!C23 -> 215.37838 | R79: 8122427
A80: 1973 | B80: 207314764 | C80: ='cohousing population'!D99 -> 78966976 | D80: ='cohousing population'!D25 -> 5021765 | F80: 3129 | J80: ='elm- g'!C24 -> 147.98152 | K80: ='elm- j'!C24 -> 145.96804 | L80: ='elm-i'!C24 -> 48.533628 | M80: ='elm- uk'!C24 -> 148.58977 | N80: ='elm- us'!C24 -> 206.86047 | R80: 8137164
A81: 1974 | B81: 209277968 | C81: ='cohousing population'!D100 -> 78996693 | D81: ='cohousing population'!D26 -> 5045638 | F81: 3129 | J81: ='elm- g'!C25 -> 150.34413 | K81: ='elm- j'!C25 -> 143.07278 | L81: ='elm-i'!C25 -> 49.071266 | M81: ='elm- uk'!C25 -> 151.05761 | N81: ='elm- us'!C25 -> 217.57302 | R81: 8160636
A82: 1975 | B82: 211274535 | C82: ='cohousing population'!D101 -> 78701861 | D82: ='cohousing population'!D27 -> 5060403 | F82: 3129 | J82: ='elm- g'!C26 -> 150.21146 | K82: ='elm- j'!C26 -> 142.55302 | L82: ='elm-i'!C26 -> 49.427351 | M82: ='elm- uk'!C26 -> 139.35072 | N82: ='elm- us'!C26 -> 216.31835 | R82: 8192642
A83: 1976 | B83: 213270022 | C83: ='cohousing population'!D102 -> 78364503 | D83: ='cohousing population'!D28 -> 5072804 | F83: 3129 | J83: ='elm- g'!C27 -> 151.62391 | K83: ='elm- j'!C27 -> 143.84402 | L83: ='elm-i'!C27 -> 49.825605 | M83: ='elm- uk'!C27 -> 133.00823 | N83: ='elm- us'!C27 -> 218.84763 | R83: 8222393
A84: 1977 | B84: 215437405 | C84: ='cohousing population'!D103 -> 78185560 | D84: ='cohousing population'!D29 -> 5088574 | F84: 3129 | J84: ='elm- g'!C28 -> 157.21597 | K84: ='elm- j'!C28 -> 149.87519 | L84: ='elm-i'!C28 -> 50.27923 | M84: ='elm- uk'!C28 -> 158.25168 | N84: ='elm- us'!C28 -> 225.64588 | R84: 8251698
A85: 1978 | B85: 217881437 | C85: ='cohousing population'!D104 -> 78115357 | D85: ='cohousing population'!D30 -> 5104342 | F85: 3129 | J85: ='elm- g'!C29 -> 162.15526 | K85: ='elm- j'!C29 -> 151.75553 | L85: ='elm-i'!C29 -> 50.771496 | M85: ='elm- uk'!C29 -> 147.97242 | N85: ='elm- us'!C29 -> 223.04374 | R85: 8275793
A86: 1979 | B86: 220463115 | C86: ='cohousing population'!D105 -> 78147899 | D86: ='cohousing population'!D31 -> 5116861 | F86: 3129 | J86: ='elm- g'!C30 -> 164.33061 | K86: ='elm- j'!C30 -> 151.38652 | L86: ='elm-i'!C30 -> 51.043366 | M86: ='elm- uk'!C30 -> 152.45412 | N86: ='elm- us'!C30 -> 225.34364 | R86: 8293749
A87: 1980 | B87: 226545805 | C87: ='cohousing population'!D106 -> 78315374 | D87: ='cohousing population'!D32 -> 5123078 | E87: 528747 | F87: 3129 | J87: ='elm- g'!C31 -> 164.55313 | K87: ='elm- j'!C31 -> 150.56591 | L87: ='elm-i'!C31 -> 51.397191 | M87: ='elm- uk'!C31 -> 149.18805 | N87: ='elm- us'!C31 -> 217.19931 | R87: 8310470 | V87: ='energy communities population'!D73 -> 14162687
A88: 1981 | B88: 228670000 | C88: ='cohousing population'!D107 -> 78448044 | D88: ='cohousing population'!D33 -> 5121628 | E88: =(($E$97-$E$87)/10)+E87 -> 536053.9 | F88: =((F97-F87)/10)+F87 -> 3129 | J88: ='elm- g'!C32 -> 170.21705 | K88: ='elm- j'!C32 -> 152.45925 | L88: ='elm-i'!C32 -> 52.193175 | M88: ='elm- uk'!C32 -> 147.39294 | N88: ='elm- us'!C32 -> 216.37797 | R88: 8320460 | V88: ='energy communities population'!D74 -> 14262690
A89: 1982 | B89: 230997000 | C89: ='cohousing population'!D108 -> 78393671 | D89: ='cohousing population'!D34 -> 5117897 | E89: =(($E$97-$E$87)/10)+E88 -> 543360.8 | F89: 3129 | J89: ='elm- g'!C33 -> 167.0054 | K89: ='elm- j'!C33 -> 152.51014 | L89: ='elm-i'!C33 -> 53.235543 | M89: ='elm- uk'!C33 -> 154.86522 | N89: ='elm- us'!C33 -> 224.61058 | R89: 8325179 | V89: ='energy communities population'!D75 -> 14333902
A90: 1983 | B90: 233307000 | C90: ='cohousing population'!D109 -> 78224137 | D90: ='cohousing population'!D35 -> 5114468 | E90: =(($E$97-$E$87)/10)+E89 -> 550667.7 | F90: 3129 | J90: ='elm- g'!C34 -> 166.14676 | K90: ='elm- j'!C34 -> 148.22741 | L90: ='elm-i'!C34 -> 54.166377 | M90: ='elm- uk'!C34 -> 149.42382 | N90: ='elm- us'!C34 -> 218.85577 | R90: 8328917 | V90: ='energy communities population'!D76 -> 14396901
A91: 1984 | B91: 235825000 | C91: ='cohousing population'!D110 -> 77998199 | D91: ='cohousing population'!D36 -> 5111830 | E91: =(($E$97-$E$87)/10)+E90 -> 557974.6 | F91: 3129 | J91: ='elm- g'!C35 -> 172.89805 | K91: ='elm- j'!C35 -> 153.1616 | L91: ='elm-i'!C35 -> 54.662507 | M91: ='elm- uk'!C35 -> 153.8559 | N91: ='elm- us'!C35 -> 227.08407 | R91: 8336484 | V91: ='energy communities population'!D77 -> 14462810
A92: 1985 | B92: 238466000 | C92: ='cohousing population'!D111 -> 77863423 | D92: ='cohousing population'!D37 -> 5113878 | E92: =(($E$97-$E$87)/10)+E91 -> 565281.5 | F92: 3129 | J92: ='elm- g'!C36 -> 172.06177 | K92: ='elm- j'!C36 -> 151.79048 | L92: ='elm-i'!C36 -> 54.774746 | M92: ='elm- uk'!C36 -> 152.09297 | N92: ='elm- us'!C36 -> 228.23478 | R92: 8350249 | V92: ='energy communities population'!D78 -> 14538958
A93: 1986 | B93: 241116000 | C93: ='cohousing population'!D112 -> 77923807 | D93: ='cohousing population'!D38 -> 5120691 | E93: =(($E$97-$E$87)/10)+E92 -> 572588.4 | F93: 3129 | J93: ='elm- g'!C37 -> 173.8649 | K93: ='elm- j'!C37 -> 155.72247 | L93: ='elm-i'!C37 -> 55.263531 | M93: ='elm- uk'!C37 -> 154.55767 | N93: ='elm- us'!C37 -> 225.34665 | R93: 8369682 | V93: ='energy communities population'!D79 -> 14626489
A94: 1987 | B94: 243829000 | C94: ='cohousing population'!D113 -> 78062321 | D94: ='cohousing population'!D39 -> 5127135 | E94: =(($E$97-$E$87)/10)+E93 -> 579895.3 | F94: 3129 | J94: ='elm- g'!C38 -> 175.35144 | K94: ='elm- j'!C38 -> 156.79455 | L94: ='elm-i'!C38 -> 56.242225 | M94: ='elm- uk'!C38 -> 154.16371 | N94: ='elm- us'!C38 -> 231.13596 | R94: 8397651 | V94: ='energy communities population'!D80 -> 14724947
A95: 1988 | B95: 246551000 | C95: ='cohousing population'!D114 -> 78385993 | D95: ='cohousing population'!D40 -> 5129650 | E95: =(($E$97-$E$87)/10)+E94 -> 587202.2 | F95: 3129 | J95: ='elm- g'!C39 -> 177.01437 | K95: ='elm- j'!C39 -> 155.79831 | L95: ='elm-i'!C39 -> 56.247038 | M95: ='elm- uk'!C39 -> 161.21136 | N95: ='elm- us'!C39 -> 226.31839 | R95: 8436358 | V95: ='energy communities population'!D81 -> 14825916
A96: 1989 | B96: 249439000 | C96: ='cohousing population'!D115 -> 79007063 | D96: ='cohousing population'!D41 -> 5132717 | E96: =(($E$97-$E$87)/10)+E95 -> 594509.1 | F96: 3129 | J96: ='elm- g'!C40 -> 173.00012 | K96: ='elm- j'!C40 -> 156.91576 | L96: ='elm-i'!C40 -> 56.068005 | M96: ='elm- uk'!C40 -> 158.47103 | N96: ='elm- us'!C40 -> 238.73136 | R96: 8492819 | V96: ='energy communities population'!D82 -> 14921107
A97: 1990 | B97: 248709873 | C97: ='cohousing population'!D116 -> 79707964 | D97: ='cohousing population'!D42 -> 5141025 | E97: 601816 | F97: 3129 | J97: ='elm- g'!C41 -> 170.22194 | K97: ='elm- j'!C41 -> 153.22844 | L97: ='elm-i'!C41 -> 56.079244 | M97: ='elm- uk'!C41 -> 160.78072 | N97: ='elm- us'!C41 -> 235.36004 | R97: 8558569 | V97: ='energy communities population'!D83 -> 15030884
...

Sheet active mobility
A1: Column1 | B1: Column2 | C1: Column3 | D1: Column4 | E1: Column5 | F1: Column6 | G1: Column7 | H1: Column8 | I1: Column9 | J1: Column10 | K1: Column11 | L1: Column12 | M1: Column13 | N1: Column14 | O1: Column15 | P1: Column16 | Q1: Column17 | R1: Column18 | S1: Column19 | T1: Column20 | U1: Column21 | V1: Column22 | W1: Column23 | X1: Column24 | Y1: Column25 | Z1: Column26 | AA1: Column27 | AB1: Column28 | AC1: Column29 | AD1: Column30 | AE1: Column31 | AF1: Column32 | AG1: Column33 | AH1: Column34 | AI1: Column35 | AJ1: Column36 | AK1: Column37 | AL1: Column38 | AM1: Column39 | AN1: Column40 | AO1: Column41 | AP1: Column42 | AQ1: Column43 | AR1: Column44 | AS1: Column45 | AT1: Column46 | AU1: Column47 | AV1: Column48 | AW1: Column49 | AX1: Column50 | AY1: Column51 | AZ1: Column52 | BA1: Column53 | BB1: Column54 | BC1: Column55 | BD1: Column56 | BE1: Column57 | BF1: Column58 | BG1: Column59 | BH1: Column60 | BI1: Column61 | BJ1: Column62 | BK1: Column63 | BL1: Column64 | BM1: Column65 | BN1: Column66 | BO1: Column67 | BP1: Column68 | BQ1: Column69 | BR1: Column70 | BS1: Column71 | BT1: Column72 | BU1: Column73 | BV1: Column74 | BW1: Column75 | BX1: Column76 | BY1: Column77 | BZ1: Column78 | CA1: Column79 | CB1: Column80 | CC1: Column81 | CD1: Column82 | CE1: Column83 | CF1: Column84 | CG1: Column85 | CH1: Column86 | CI1: Column87 | CJ1: Column88 | CK1: Column89 | CL1: Column90 | CM1: Column91 | CN1: Column92 | CO1: Column93 | CP1: Column94 | CQ1: Column95 | CR1: Column96 | CS1: Column97 | CT1: Column98 | CU1: Column99 | CV1: Column100 | CW1: Column101 | CX1: Column102 | CY1: Column103 | CZ1: Column104 | DA1: Column105 | DB1: Column106 | DC1: Column107 | DD1: Column108 | DE1: Column109 | DF1: Column110 | DG1: Column111 | DH1: Column112 | DI1: Column113 | DJ1: Column114 | DK1: Column1142 | DL1: Column1143 | DM1: Column115 | DN1: Column116 | DO1: Column117 | DP1: Column118 | DQ1: Column119 | DR1: Column120 | DS1: Column121 | DT1: Column122 | DU1: Column123 | DV1: Column124 | DW1: Column125 | DX1: Column126 | DY1: Column127 | DZ1: Column128 | EA1: Column129 | EB1: Column130 | EC1: Column131 | ED1: Column132 | EE1: Column133 | EF1: Column134 | EG1: Column135 | EH1: Column136 | EI1: Column137 | EJ1: Column138 | EK1: Column139 | EL1: Column140 | EM1: Column141 | EN1: Column142 | EO1: Column143 | EP1: Column144 | EQ1: Column145 | ER1: Column146 | ES1: Column147 | ET1: Column148 | EU1: Column149 | EV1: Column150 | EW1: Column151 | EX1: Column152 | EY1: Column153 | EZ1: Column154 | FA1: Column155 | FB1: Column156 | FC1: Column157 | FD1: Column158 | FE1: Column159 | FF1: Column160
A2: Downloaded from: https://www.eea.europa.eu/en/analysis/publications/sustainability-of-europes-mobility-systems/passenger-transport-activity/eu-27-passenger-transport-activity-gpkm-for-different-transport-modes-according-to-the-ff55-mix-scenario
A4: Publisher | B4: European Environment Agency | C4: EEA
A6: Sources | B6: https://energy.ec.europa.eu/publications/excel-files-mix-scenario_en | C6: EC, 2021d, ‘Excel files for MIX scenario - FF55 MIX energy-transport-ghg’
A8: Geographical coverage | B8: Cyprus, Portugal, Spain, Malta, Denmark, United Kingdom, Sweden, Netherlands, Austria, Belgium, Germany, Luxembourg, Ireland, France, Slovakia, Czechia, Italy, Slovenia, Greece, Estonia, Latvia, Lithuania, Finland, Hungary, Bulgaria, Poland, Romania
A10: Scenario_EU-27_x1 | B10: Scenario_EU-27_Domestic_and_intra-EU_aviation | C10: Scenario_EU-27_Domestic_navigation_ | D10: Scenario_EU-27_Rail_ | E10: Scenario_EU-27_Powered_two-wheelers_ | F10: Scenario_EU-27_Buses_and_coaches_ | G10: Scenario_EU-27_Cars__ | H10: Scenario_BE_Domestic_and_intra-EU_aviation | I10: Scenario_BE_Domestic_navigation_ | J10: Scenario_BE_Rail_ | K10: Scenario_BE_Powered_two-wheelers_ | L10: Scenario_BE_Buses_and_coaches_ | M10: Scenario_BE_Cars__ | N10: Scenario_BG_Domestic_and_intra-EU_aviation | O10: Scenario_BG_Domestic_navigation_ | P10: Scenario_BG_Rail_ | Q10: Scenario_BG_Powered_two-wheelers_ | R10: Scenario_BG_Buses_and_coaches_ | S10: Scenario_BG_Cars__ | T10: Scenario_CZ_Domestic_and_intra-EU_aviation | U10: Scenario_CZ_Domestic_navigation_ | V10: Scenario_CZ_Rail_ | W10: Scenario_CZ_Powered_two-wheelers_ | X10: Scenario_CZ_Buses_and_coaches_ | Y10: Scenario_CZ_Cars__ | Z10: Scenario_DK_Domestic_and_intra-EU_aviation | AA10: Scenario_DK_Domestic_navigation_ | AB10: Scenario_DK_Rail_ | AC10: Scenario_DK_Powered_two-wheelers_ | AD10: Scenario_DK_Buses_and_coaches_ | AE10: Scenario_DK_Cars__ | AF10: Scenario_DE_Domestic_and_intra-EU_aviation | AG10: Scenario_DE_Domestic_navigation_ | AH10: Scenario_DE_Rail_ | AI10: Scenario_DE_Powered_two-wheelers_ | AJ10: Scenario_DE_Buses_and_coaches_ | AK10: Scenario_DE_Cars__ | AL10: Scenario_EE_Domestic_and_intra-EU_aviation | AM10: Scenario_EE_Domestic_navigation_ | AN10: Scenario_EE_Rail_ | AO10: Scenario_EE_Powered_two-wheelers_ | AP10: Scenario_EE_Buses_and_coaches_ | AQ10: Scenario_EE_Cars__ | AR10: Scenario_IE_Domestic_and_intra-EU_aviation | AS10: Scenario_IE_Domestic_navigation_ | AT10: Scenario_IE_Rail_ | AU10: Scenario_IE_Powered_two-wheelers_ | AV10: Scenario_IE_Buses_and_coaches_ | AW10: Scenario_IE_Cars__ | AX10: Scenario_EL_Domestic_and_intra-EU_aviation | AY10: Scenario_EL_Domestic_navigation_ | AZ10: Scenario_EL_Rail_ | BA10: Scenario_EL_Powered_two-wheelers_ | BB10: Scenario_EL_Buses_and_coaches_ | BC10: Scenario_EL_Cars__ | BD10: Scenario_ES_Domestic_and_intra-EU_aviation | BE10: Scenario_ES_Domestic_navigation_ | BF10: Scenario_ES_Rail_ | BG10: Scenario_ES_Powered_two-wheelers_ | BH10: Scenario_ES_Buses_and_coaches_ | BI10: Scenario_ES_Cars__ | BJ10: Scenario_FR_Domestic_and_intra-EU_aviation | BK10: Scenario_FR_Domestic_navigation_ | BL10: Scenario_FR_Rail_ | BM10: Scenario_FR_Powered_two-wheelers_ | BN10: Scenario_FR_Buses_and_coaches_ | BO10: Scenario_FR_Cars__ | BP10: Scenario_HR_Domestic_and_intra-EU_aviation | BQ10: Scenario_HR_Domestic_navigation_ | BR10: Scenario_HR_Rail_ | BS10: Scenario_HR_Powered_two-wheelers_ | BT10: Scenario_HR_Buses_and_coaches_ | BU10: Scenario_HR_Cars__ | BV10: Scenario_IT_Domestic_and_intra-EU_aviation | BW10: Scenario_IT_Domestic_navigation_ | BX10: Scenario_IT_Rail_ | BY10: Scenario_IT_Powered_two-wheelers_ | BZ10: Scenario_IT_Buses_and_coaches_ | CA10: Scenario_IT_Cars__ | CB10: Scenario_CY_Domestic_and_intra-EU_aviation | CC10: Scenario_CY_Powered_two-wheelers_ | CD10: Scenario_CY_Buses_and_coaches_ | CE10: Scenario_CY_Cars__ | CF10: Scenario_LV_Domestic_and_intra-EU_aviation | CG10: Scenario_LV_Rail_ | CH10: Scenario_LV_Powered_two-wheelers_ | CI10: Scenario_LV_Buses_and_coaches_ | CJ10: Scenario_LV_Cars__ | CK10: Scenario_LT_Domestic_and_intra-EU_aviation | CL10: Scenario_LT_Domestic_navigation_ | CM10: Scenario_LT_Rail_ | CN10: Scenario_LT_Powered_two-wheelers_ | CO10: Scenario_LT_Buses_and_coaches_ | CP10: Scenario_LT_Cars__ | CQ10: Scenario_LU_Domestic_and_intra-EU_aviation | CR10: Scenario_LU_Rail_ | CS10: Scenario_LU_Powered_two-wheelers_ | CT10: Scenario_LU_Buses_and_coaches_ | CU10: Scenario_LU_Cars__ | CV10: Scenario_HU_Domestic_and_intra-EU_aviation | CW10: Scenario_HU_Rail_ | CX10: Scenario_HU_Powered_two-wheelers_ | CY10: Scenario_HU_Buses_and_coaches_ | CZ10: Scenario_HU_Cars__ | DA10: Scenario_MT_Domestic_and_intra-EU_aviation | DB10: Scenario_MT_Powered_two-wheelers_ | DC10: Scenario_MT_Buses_and_coaches_ | DD10: Scenario_MT_Cars__ | DE10: Scenario_NL_Domestic_and_intra-EU_aviation | DF10: Scenario_NL_Domestic_navigation_ | DG10: Scenario_NL_Rail_ | DH10: Scenario_NL_Powered_two-wheelers_ | DI10: Scenario_NL_Buses_and_coaches_ | DJ10: Scenario_NL_Cars__ | DK10: total Gpkm NL | DL10: total pkm NL (millions) | DM10: Scenario_AT_Domestic_and_intra-EU_aviation | DN10: Scenario_AT_Domestic_navigation_ | DO10: Scenario_AT_Rail_ | DP10: Scenario_AT_Powered_two-wheelers_ | DQ10: Scenario_AT_Buses_and_coaches_ | DR10: Scenario_AT_Cars__ | DS10: Scenario_PL_Domestic_and_intra-EU_aviation | DT10: Scenario_PL_Domestic_navigation_ | DU10: Scenario_PL_Rail_ | DV10: Scenario_PL_Powered_two-wheelers_ | DW10: Scenario_PL_Buses_and_coaches_ | DX10: Scenario_PL_Cars__ | DY10: Scenario_PT_Domestic_and_intra-EU_aviation | DZ10: Scenario_PT_Domestic_navigation_ | EA10: Scenario_PT_Rail_ | EB10: Scenario_PT_Powered_two-wheelers_ | EC10: Scenario_PT_Buses_and_coaches_ | ED10: Scenario_PT_Cars__ | EE10: Scenario_RO_Domestic_and_intra-EU_aviation | EF10: Scenario_RO_Domestic_navigation_ | EG10: Scenario_RO_Rail_ | EH10: Scenario_RO_Powered_two-wheelers_ | EI10: Scenario_RO_Buses_and_coaches_ | EJ10: Scenario_RO_Cars__ | EK10: Scenario_SI_Domestic_and_intra-EU_aviation | EL10: Scenario_SI_Rail_ | EM10: Scenario_SI_Powered_two-wheelers_ | EN10: Scenario_SI_Buses_and_coaches_ | EO10: Scenario_SI_Cars__ | EP10: Scenario_SK_Domestic_and_intra-EU_aviation | EQ10: Scenario_SK_Rail_ | ER10: Scenario_SK_Powered_two-wheelers_ | ES10: Scenario_SK_Buses_and_coaches_ | ET10: Scenario_SK_Cars__ | EU10: Scenario_FI_Domestic_and_intra-EU_aviation | EV10: Scenario_FI_Domestic_navigation_ | EW10: Scenario_FI_Rail_ | EX10: Scenario_FI_Powered_two-wheelers_ | EY10: Scenario_FI_Buses_and_coaches_ | EZ10: Scenario_FI_Cars__ | FA10: Scenario_SE_Domestic_and_intra-EU_aviation | FB10: Scenario_SE_Domestic_navigation_ | FC10: Scenario_SE_Rail_ | FD10: Scenario_SE_Powered_two-wheelers_ | FE10: Scenario_SE_Buses_and_coaches_ | FF10: Scenario_SE_Cars__
A12: 2005 | B12: 372.7858992472852 | C12: 32.267954693360714 | D12: 417.2232059259342 | E12: 115.14315895057229 | F12: 498.20252417552103 | G12: 3841.202448424538 | H12: 7.334669746070221 | I12: 0.31036525987373126 | J12: 9.439999999580914 | K12: 1.2061707550892904 | L12: 17.51504805873601 | M12: 102.80426445720657 | N12: 2.6867978866624043 | O12: 0.017054319009891183 | P12: 2.823000400005723 | Q12: 0.7300005997425607 | R12: 13.687999999648689 | S12: 35.100000394388935 | T12: 7.901735783151914 | U12: 0 | V12: 14.601200399989139 | W12: 3.1500005999995206 | X12: 15.607899999997127 | Y12: 68.6400004000203 | Z12: 8.230279364858626 | AA12: 3.162622907706997 | AB12: 6.136000402903621 | AC12: 0.530000600004417 | AD12: 7.169000004636504 | AE12: 49.75800042521359 | AF12: 57.33419735428041 | AG12: 2.1390798828915596 | AH12: 92.28499999525916 | AI12: 18.79500063505142 | AJ12: 67.06199999873272 | AK12: 856.8750005669788 | AL12: 0.6054875415023772 | AM12: 0.3786122992229439 | AN12: 0.32330039674928507 | AO12: 0.11000219817238241 | AP12: 2.7159999675913387 | AQ12: 9.929001154406441 | AR12: 8.12194894150643 | AS12: 1.04240242544689 | AT12: 1.890999999840106 | AU12: 0.13000059999048896 | AV12: 7.915199999319714 | AW12: 44.3790005979474 | AX12: 23.03355036175256 | AY12: 7.46030379911707 | AZ12: 3.3540000002436727 | BA12: 4.700000601058661 | BB12: 21.70000000045052 | BC12: 85.00000060775538 | BD12: 96.3759805132985 | BE12: 1.8016814335940823 | BF12: 27.62399997915012 | BG12: 8.600000598831526 | BH12: 53.17599997245606 | BI12: 337.7970004477496 | BJ12: 57.06918435126796 | BK12: 3.3064960064113365 | BL12: 95.92033045742691 | BM12: 12.618933029226813 | BN12: 50.10470892826654 | BO12: 704.6155541266967 | BP12: 0.8811855101807338 | BQ12: 4.000000004251529e-7 | BR12: 1.7601664009869833 | BS12: 0.14800139949415755 | BT12: 3.403468986171076 | BU12: 24.000000726744556 | BV12: 36.62557812609449 | BW12: 4.9834166267071325 | BX12: 56.123000000078534 | BY12: 49.52100063068344 | BZ12: 100.95399999774675 | CA12: 677.0140004846444 | CB12: 2.867629441929434 | CC12: 0.1350008000026191 | CD12: 1.2599999986434272 | CE12: 4.800000600065487 | CF12: 0.654071948426312 | CG12: 1.1617003993274675 | CH12: 0.3300005997612335 | CI12: 2.8909999997028573 | CJ12: 12.111500598493969 | CK12: 0.6266148402989704 | CL12: 0.06779417980060119 | CM12: 0.2800012000009759 | CN12: 0.3400021999975373 | CO12: 3.691000000054629 | CP12: 34.79300059871458 | CQ12: 0.5789759587490495 | CR12: 0.26700120000126304 | CS12: 0.150000800000825 | CT12: 0.8000000000018809 | CU12: 6.300000800037398 | CV12: 2.8545191897262283 | CW12: 12.204000400000721 | CX12: 1.1000003999998145 | CY12: 17.844999999999178 | CZ12: 49.40300039996766 | DA12: 1.2115506418871431 | DB12: 0.05000080000818583 | DC12: 0.4899999981389671 | DD12: 2.0000006005021116 | DE12: 12.537254688854759 | DF12: 0.7500633152809575 | DG12: 15.899406410093045 | DH12: 2.700000601154671 | DI12: 4.775028044045083 | DJ12: 148.80000039109697 | DK12: =SUM(DE12+DJ12) -> 161.33726 | DL12: =DK12*1000 -> 161337.26 | DM12: 6.011271421153518 | DN12: 0.036243219902651 | DO12: 15.122253026692238 | DP12: 1.833880227445236 | DQ12: 9.658124698942634 | DR12: 70.5570004218626 | DS12: 3.0903190648935746 | DT12: 0.20812534343699068 | DU12: 22.557000443979728 | DV12: 1.29800060356116 | DW12: 49.20000003001622 | DX12: 152.30000051912316 | DY12: 12.122919717654312 | DZ12: 0.31373654863094613 | EA12: 4.656715883007572 | EB12: 2.000000568181055 | EC12: 6.3762630465726495 | ED12: 85.00000041584175 | EE12: 2.692465143617606 | EF12: 0.01586238902343719 | EG12: 14.581908400006851 | EH12: 2.350000799996887 | EI12: 11.811000000005397 | EJ12: 61.00000040000471 | EK12: 0.2886740566672655 | EL12: 0.7160022000277325 | EM12: 0.2300008000179384 | EN12: 3.0620000002236343 | EO12: 22.509000801367197 | EP12: 0.9183279376886472 | EQ12: 2.5682179314202283 | ER12: 0.5700009989923701 | ES12: 8.537782444697779 | ET12: 25.824000570251677 | EU12: 7.915123959999033 | EV12: 0.1412900000296127 | EW12: 4.004000000559068 | EX12: 0.9000006000368549 | EY12: 7.540000000086642 | EZ12: 61.91000060585705 | FA12: 12.215585755112732 | FB12: 6.1328043372738845 | FC12: 10.923999998603128 | FD12: 0.9171559040712132 | FE12: 9.254000000637138 | FF12: 107.98311631159912
A13: 2006 | B13: null | C13: null | D13: null | E13: null | F13: null | G13: null | H13: null | I13: null | J13: null | K13: null | L13: null | M13: null | N13: null | O13: null | P13: null | Q13: null | R13: null | S13: null | T13: null | U13: null | V13: null | W13: null | X13: null | Y13: null | Z13: null | AA13: null | AB13: null | AC13: null | AD13: null | AE13: null | AF13: null | AG13: null | AH13: null | AI13: null | AJ13: null | AK13: null | AL13: null | AM13: null | AN13: null | AO13: null | AP13: null | AQ13: null | AR13: null | AS13: null | AT13: null | AU13: null | AV13: null | AW13: null | AX13: null | AY13: null | AZ13: null | BA13: null | BB13: null | BC13: null | BD13: null | BE13: null | BF13: null | BG13: null | BH13: null | BI13: null | BJ13: null | BK13: null | BL13: null | BM13: null | BN13: null | BO13: null | BP13: null | BQ13: null | BR13: null | BS13: null | BT13: null | BU13: null | BV13: null | BW13: null | BX13: null | BY13: null | BZ13: null | CA13: null | CB13: null | CC13: null | CD13: null | CE13: null | CF13: null | CG13: null | CH13: null | CI13: null | CJ13: null | CK13: null | CL13: null | CM13: null | CN13: null | CO13: null | CP13: null | CQ13: null | CR13: null | CS13: null | CT13: null | CU13: null | CV13: null | CW13: null | CX13: null | CY13: null | CZ13: null | DA13: null | DB13: null | DC13: null | DD13: null | DE13: null | DF13: null | DG13: null | DH13: null | DI13: null | DJ13: null | DL13: =($DL$17-$DL$12)/5 + DL12 -> 160499.1 | DM13: null | DN13: null | DO13: null | DP13: null | DQ13: null | DR13: null | DS13: null | DT13: null | DU13: null | DV13: null | DW13: null | DX13: null | DY13: null | DZ13: null | EA13: null | EB13: null | EC13: null | ED13: null | EE13: null | EF13: null | EG13: null | EH13: null | EI13: null | EJ13: null | EK13: null | EL13: null | EM13: null | EN13: null | EO13: null | EP13: null | EQ13: null | ER13: null | ES13: null | ET13: null | EU13: null | EV13: null | EW13: null | EX13: null | EY13: null | EZ13: null | FA13: null | FB13: null | FC13: null | FD13: null | FE13: null | FF13: null
A14: 2007 | B14: null | C14: null | D14: null | E14: null | F14: null | G14: null | H14: null | I14: null | J14: null | K14: null | L14: null | M14: null | N14: null | O14: null | P14: null | Q14: null | R14: null | S14: null | T14: null | U14: null | V14: null | W14: null | X14: null | Y14: null | Z14: null | AA14: null | AB14: null | AC14: null | AD14: null | AE14: null | AF14: null | AG14: null | AH14: null | AI14: null | AJ14: null | AK14: null | AL14: null | AM14: null | AN14: null | AO14: null | AP14: null | AQ14: null | AR14: null | AS14: null | AT14: null | AU14: null | AV14: null | AW14: null | AX14: null | AY14: null | AZ14: null | BA14: null | BB14: null | BC14: null | BD14: null | BE14: null | BF14: null | BG14: null | BH14: null | BI14: null | BJ14: null | BK14: null | BL14: null | BM14: null | BN14: null | BO14: null | BP14: null | BQ14: null | BR14: null | BS14: null | BT14: null | BU14: null | BV14: null | BW14: null | BX14: null | BY14: null | BZ14: null | CA14: null | CB14: null | CC14: null | CD14: null | CE14: null | CF14: null | CG14: null | CH14: null | CI14: null | CJ14: null | CK14: null | CL14: null | CM14: null | CN14: null | CO14: null | CP14: null | CQ14: null | CR14: null | CS14: null | CT14: null | CU14: null | CV14: null | CW14: null | CX14: null | CY14: null | CZ14: null | DA14: null | DB14: null | DC14: null | DD14: null | DE14: null | DF14: null | DG14: null | DH14: null | DI14: null | DJ14: null | DL14: =($DL$17-$DL$12)/5 + DL13 -> 159660.94 | DM14: null | DN14: null | DO14: null | DP14: null | DQ14: null | DR14: null | DS14: null | DT14: null | DU14: null | DV14: null | DW14: null | DX14: null | DY14: null | DZ14: null | EA14: null | EB14: null | EC14: null | ED14: null | EE14: null | EF14: null | EG14: null | EH14: null | EI14: null | EJ14: null | EK14: null | EL14: null | EM14: null | EN14: null | EO14: null | EP14: null | EQ14: null | ER14: null | ES14: null | ET14: null | EU14: null | EV14: null | EW14: null | EX14: null | EY14: null | EZ14: null | FA14: null | FB14: null | FC14: null | FD14: null | FE14: null | FF14: null
A15: 2008 | B15: null | C15: null | D15: null | E15: null | F15: null | G15: null | H15: null | I15: null | J15: null | K15: null | L15: null | M15: null | N15: null | O15: null | P15: null | Q15: null | R15: null | S15: null | T15: null | U15: null | V15: null | W15: null | X15: null | Y15: null | Z15: null | AA15: null | AB15: null | AC15: null | AD15: null | AE15: null | AF15: null | AG15: null | AH15: null | AI15: null | AJ15: null | AK15: null | AL15: null | AM15: null | AN15: null | AO15: null | AP15: null | AQ15: null | AR15: null | AS15: null | AT15: null | AU15: null | AV15: null | AW15: null | AX15: null | AY15: null | AZ15: null | BA15: null | BB15: null | BC15: null | BD15: null | BE15: null | BF15: null | BG15: null | BH15: null | BI15: null | BJ15: null | BK15: null | BL15: null | BM15: null | BN15: null | BO15: null | BP15: null | BQ15: null | BR15: null | BS15: null | BT15: null | BU15: null | BV15: null | BW15: null | BX15: null | BY15: null | BZ15: null | CA15: null | CB15: null | CC15: null | CD15: null | CE15: null | CF15: null | CG15: null | CH15: null | CI15: null | CJ15: null | CK15: null | CL15: null | CM15: null | CN15: null | CO15: null | CP15: null | CQ15: null | CR15: null | CS15: null | CT15: null | CU15: null | CV15: null | CW15: null | CX15: null | CY15: null | CZ15: null | DA15: null | DB15: null | DC15: null | DD15: null | DE15: null | DF15: null | DG15: null | DH15: null | DI15: null | DJ15: null | DL15: =($DL$17-$DL$12)/5 + DL14 -> 158822.79 | DM15: null | DN15: null | DO15: null | DP15: null | DQ15: null | DR15: null | DS15: null | DT15: null | DU15: null | DV15: null | DW15: null | DX15: null | DY15: null | DZ15: null | EA15: null | EB15: null | EC15: null | ED15: null | EE15: null | EF15: null | EG15: null | EH15: null | EI15: null | EJ15: null | EK15: null | EL15: null | EM15: null | EN15: null | EO15: null | EP15: null | EQ15: null | ER15: null | ES15: null | ET15: null | EU15: null | EV15: null | EW15: null | EX15: null | EY15: null | EZ15: null | FA15: null | FB15: null | FC15: null | FD15: null | FE15: null | FF15: null
A16: 2009 | B16: null | C16: null | D16: null | E16: null | F16: null | G16: null | H16: null | I16: null | J16: null | K16: null | L16: null | M16: null | N16: null | O16: null | P16: null | Q16: null | R16: null | S16: null | T16: null | U16: null | V16: null | W16: null | X16: null | Y16: null | Z16: null | AA16: null | AB16: null | AC16: null | AD16: null | AE16: null | AF16: null | AG16: null | AH16: null | AI16: null | AJ16: null | AK16: null | AL16: null | AM16: null | AN16: null | AO16: null | AP16: null | AQ16: null | AR16: null | AS16: null | AT16: null | AU16: null | AV16: null | AW16: null | AX16: null | AY16: null | AZ16: null | BA16: null | BB16: null | BC16: null | BD16: null | BE16: null | BF16: null | BG16: null | BH16: null | BI16: null | BJ16: null | BK16: null | BL16: null | BM16: null | BN16: null | BO16: null | BP16: null | BQ16: null | BR16: null | BS16: null | BT16: null | BU16: null | BV16: null | BW16: null | BX16: null | BY16: null | BZ16: null | CA16: null | CB16: null | CC16: null | CD16: null | CE16: null | CF16: null | CG16: null | CH16: null | CI16: null | CJ16: null | CK16: null | CL16: null | CM16: null | CN16: null | CO16: null | CP16: null | CQ16: null | CR16: null | CS16: null | CT16: null | CU16: null | CV16: null | CW16: null | CX16: null | CY16: null | CZ16: null | DA16: null | DB16: null | DC16: null | DD16: null | DE16: null | DF16: null | DG16: null | DH16: null | DI16: null | DJ16: null | DL16: =($DL$17-$DL$12)/5 + DL15 -> 157984.63 | DM16: null | DN16: null | DO16: null | DP16: null | DQ16: null | DR16: null | DS16: null | DT16: null | DU16: null | DV16: null | DW16: null | DX16: null | DY16: null | DZ16: null | EA16: null | EB16: null | EC16: null | ED16: null | EE16: null | EF16: null | EG16: null | EH16: null | EI16: null | EJ16: null | EK16: null | EL16: null | EM16: null | EN16: null | EO16: null | EP16: null | EQ16: null | ER16: null | ES16: null | ET16: null | EU16: null | EV16: null | EW16: null | EX16: null | EY16: null | EZ16: null | FA16: null | FB16: null | FC16: null | FD16: null | FE16: null | FF16: null
A17: 2010 | B17: 398.4087817082652 | C17: 31.32039841153487 | D17: 444.22344026802347 | E17: 114.66863858633572 | F17: 483.5178151183824 | G17: 3980.9477402554776 | H17: 8.907141840677824 | I17: 0.3008757616309063 | J17: 11.634000000000004 | K17: 1.2651077980312928 | L17: 17.379999999999985 | M17: 109.3877602190548 | N17: 2.894039668955549 | O17: 0.016532877556941716 | P17: 2.9990004 | Q17: 1.0400005999999997 | R17: 10.613000000000003 | S17: 46.90000039999999 | T17: 7.144064840743311 | U17: 0 | V17: 15.556000399999995 | W17: 3.5200005999999995 | X17: 16.955599999999983 | Y17: 63.570000399999984 | Z17: 9.22831493068931 | AA17: 3.0659248987329693 | AB17: 6.577000399999999 | AC17: 0.5440006 | AD17: 6.820999999999996 | AE17: 51.69100040000001 | AF17: 56.55147769109874 | AG17: 2.0736769688309433 | AH17: 100.241 | AI17: 17.700000600000006 | AJ17: 61.76700000000001 | AK17: 887.0000003999994 | AL17: 0.48032152907636433 | AM17: 0.36703613284753883 | AN17: 0.4520995999999999 | AO17: 0.19900220250568812 | AP17: 2.060999999999998 | AQ17: 10.100001399999993 | AR17: 8.338965738027968 | AS17: 1.0105307062006406 | AT17: 1.8090000000000002 | AU17: 0.12300059999999999 | AV17: 8.459200000000001 | AW17: 48.0825006 | AX17: 17.76803686192057 | AY17: 7.23220311080188 | AZ17: 3.0757464982806515 | BA17: 5.7700006 | BB17: 21.099999999999994 | BC17: 99.60000060000006 | BD17: 102.1807493748563 | BE17: 1.7465945640094833 | BF17: 30.044899999999995 | BG17: 10.140000600000004 | BH17: 50.90200000000002 | BI17: 341.6290003999999 | BJ17: 61.21052175963105 | BK17: 3.205399046270325 | BL17: 107.43220290291087 | BM17: 13.91802422496 | BN17: 54.040974622693454 | BO17: 695.8712974248097 | BP17: 1.5103436139544488 | BQ17: 0.035135074224866315 | BR17: 2.2603573999999993 | BS17: 0.1540014000000001 | BT17: 3.2484179999999974 | BU17: 25.700000799999998 | BV17: 44.71491368630151 | BW17: 4.8310473916636 | BX17: 54.255 | BY17: 41.48000059999998 | BZ17: 102.21899999999998 | CA17: 698.3900004000001 | CB17: 2.888705966712468 | CC17: 0.13000080000000008 | CD17: 1.2900000000000005 | CE17: 5.900000599999998 | CF17: 1.5110643369980057 | CG17: 0.8640004 | CH17: 0.43000060000000007 | CI17: 2.3109999999999986 | CJ17: 12.312340600000004 | CK17: 0.8680506028721593 | CL17: 0.0657213554784777 | CM17: 0.24400120000000006 | CN17: 0.63 | CO17: 2.693599999999999 | CP17: 32.56900059999999 | CQ17: 0.5676801468664983 | CR17: 0.34700119999999984 | CS17: 0.16000080000000005 | CT17: 0.9399999999999997 | CU17: 6.5000008 | CV17: 2.9343948023316884 | CW17: 10.170000400000003 | CX17: 1.2500004000000002 | CY17: 16.460999999999977 | CZ17: 52.59500040000001 | DA17: 1.4909993561751684 | DB17: 0.060000800000000014 | DC17: 0.5 | DD17: 2.200000600000001 | DE17: 12.946477269447175 | DF17: 0.7271299380692456 | DG17: 17.753925061229808 | DH17: 3.2100005999999994 | DI17: 4.84607493877019 | DJ17: 144.2000004 | DK17: =SUM(DE17+DJ17) -> 157.14648 | DL17: =DK17*1000 -> 157146.48 | DM17: 6.518136537433558 | DN17: 0.035135074224866315 | DO17: 17.18181580782605 | DP17: 2.1358448599999993 | DQ17: 9.951612714295885 | DR17: 73.46700039999998 | DS17: 6.34171167284209 | DT17: 0.20176185766058 | DU17: 22.261000400000004 | DV17: 3.1530005999999986 | DW17: 41.70000000000001 | DX17: 188.8100005999999 | DY17: 13.49401700148777 | DZ17: 0.30414397945768823 | EA17: 5.244233000000001 | EB17: 1.8000006000000004 | EC17: 6.077555342622833 | ED17: 83.70000040000004 | EE17: 6.211370597235634 | EF17: 0.015377392443670672 | EG17: 12.575710497776036 | EH17: 2.840000799999999 | EI17: 15.812000000000006 | EJ17: 75.50000039999996 | EK17: 0.2770602403183726 | EL17: 0.7290012000000002 | EM17: 0.3300007999999998 | EN17: 3.183 | EO17: 25.636000799999994 | EP17: 0.5916190623812795 | EQ17: 2.5924435 | ER17: 0.5600009999999996 | ES17: 5.2707795000000015 | ET17: 26.87900059999999 | EU17: 7.743094874815016 | EV17: 0.1408800000000002 | EW17: 4.488999999999998 | EX17: 1.1610006000000004 | EY17: 7.540000000000002 | EZ17: 64.74500059999997 | FA17: 13.095507704415382 | FB17: 5.945292281430247 | FC17: 13.434999999999999 | FD17: 0.9656449008387554 | FE17: 9.373999999999995 | FF17: 108.01282901161349
A18: 2011 | B18: null | C18: null | D18: null | E18: null | F18: null | G18: null | H18: null | I18: null | J18: null | K18: null | L18: null | M18: null | N18: null | O18: null | P18: null | Q18: null | R18: null | S18: null | T18: null | U18: null | V18: null | W18: null | X18: null | Y18: null | Z18: null | AA18: null | AB18: null | AC18: null | AD18: null | AE18: null | AF18: null | AG18: null | AH18: null | AI18: null | AJ18: null | AK18: null | AL18: null | AM18: null | AN18: null | AO18: null | AP18: null | AQ18: null | AR18: null | AS18: null | AT18: null | AU18: null | AV18: null | AW18: null | AX18: null | AY18: null | AZ18: null | BA18: null | BB18: null | BC18: null | BD18: null | BE18: null | BF18: null | BG18: null | BH18: null | BI18: null | BJ18: null | BK18: null | BL18: null | BM18: null | BN18: null | BO18: null | BP18: null | BQ18: null | BR18: null | BS18: null | BT18: null | BU18: null | BV18: null | BW18: null | BX18: null | BY18: null | BZ18: null | CA18: null | CB18: null | CC18: null | CD18: null | CE18: null | CF18: null | CG18: null | CH18: null | CI18: null | CJ18: null | CK18: null | CL18: null | CM18: null | CN18: null | CO18: null | CP18: null | CQ18: null | CR18: null | CS18: null | CT18: null | CU18: null | CV18: null | CW18: null | CX18: null | CY18: null | CZ18: null | DA18: null | DB18: null | DC18: null | DD18: null | DE18: null | DF18: null | DG18: null | DH18: null | DI18: null | DJ18: null | DL18: =($DL$22-$DL$17)/5 + DL17 -> 157169.22 | DM18: null | DN18: null | DO18: null | DP18: null | DQ18: null | DR18: null | DS18: null | DT18: null | DU18: null | DV18: null | DW18: null | DX18: null | DY18: null | DZ18: null | EA18: null | EB18: null | EC18: null | ED18: null | EE18: null | EF18: null | EG18: null | EH18: null | EI18: null | EJ18: null | EK18: null | EL18: null | EM18: null | EN18: null | EO18: null | EP18: null | EQ18: null | ER18: null | ES18: null | ET18: null | EU18: null | EV18: null | EW18: null | EX18: null | EY18: null | EZ18: null | FA18: null | FB18: null | FC18: null | FD18: null | FE18: null | FF18: null
A19: 2012 | B19: null | C19: null | D19: null | E19: null | F19: null | G19: null | H19: null | I19: null | J19: null | K19: null | L19: null | M19: null | N19: null | O19: null | P19: null | Q19: null | R19: null | S19: null | T19: null | U19: null | V19: null | W19: null | X19: null | Y19: null | Z19: null | AA19: null | AB19: null | AC19: null | AD19: null | AE19: null | AF19: null | AG19: null | AH19: null | AI19: null | AJ19: null | AK19: null | AL19: null | AM19: null | AN19: null | AO19: null | AP19: null | AQ19: null | AR19: null | AS19: null | AT19: null | AU19: null | AV19: null | AW19: null | AX19: null | AY19: null | AZ19: null | BA19: null | BB19: null | BC19: null | BD19: null | BE19: null | BF19: null | BG19: null | BH19: null | BI19: null | BJ19: null | BK19: null | BL19: null | BM19: null | BN19: null | BO19: null | BP19: null | BQ19: null | BR19: null | BS19: null | BT19: null | BU19: null | BV19: null | BW19: null | BX19: null | BY19: null | BZ19: null | CA19: null | CB19: null | CC19: null | CD19: null | CE19: null | CF19: null | CG19: null | CH19: null | CI19: null | CJ19: null | CK19: null | CL19: null | CM19: null | CN19: null | CO19: null | CP19: null | CQ19: null | CR19: null | CS19: null | CT19: null | CU19: null | CV19: null | CW19: null | CX19: null | CY19: null | CZ19: null | DA19: null | DB19: null | DC19: null | DD19: null | DE19: null | DF19: null | DG19: null | DH19: null | DI19: null | DJ19: null | DL19: =($DL$22-$DL$17)/5 + DL18 -> 157191.96 | DM19: null | DN19: null | DO19: null | DP19: null | DQ19: null | DR19: null | DS19: null | DT19: null | DU19: null | DV19: null | DW19: null | DX19: null | DY19: null | DZ19: null | EA19: null | EB19: null | EC19: null | ED19: null | EE19: null | EF19: null | EG19: null | EH19: null | EI19: null | EJ19: null | EK19: null | EL19: null | EM19: null | EN19: null | EO19: null | EP19: null | EQ19: null | ER19: null | ES19: null | ET19: null | EU19: null | EV19: null | EW19: null | EX19: null | EY19: null | EZ19: null | FA19: null | FB19: null | FC19: null | FD19: null | FE19: null | FF19: null
A20: 2013 | B20: null | C20: null | D20: null | E20: null | F20: null | G20: null | H20: null | I20: null | J20: null | K20: null | L20: null | M20: null | N20: null | O20: null | P20: null | Q20: null | R20: null | S20: null | T20: null | U20: null | V20: null | W20: null | X20: null | Y20: null | Z20: null | AA20: null | AB20: null | AC20: null | AD20: null | AE20: null | AF20: null | AG20: null | AH20: null | AI20: null | AJ20: null | AK20: null | AL20: null | AM20: null | AN20: null | AO20: null | AP20: null | AQ20: null | AR20: null | AS20: null | AT20: null | AU20: null | AV20: null | AW20: null | AX20: null | AY20: null | AZ20: null | BA20: null | BB20: null | BC20: null | BD20: null | BE20: null | BF20: null | BG20: null | BH20: null | BI20: null | BJ20: null | BK20: null | BL20: null | BM20: null | BN20: null | BO20: null | BP20: null | BQ20: null | BR20: null | BS20: null | BT20: null | BU20: null | BV20: null | BW20: null | BX20: null | BY20: null | BZ20: null | CA20: null | CB20: null | CC20: null | CD20: null | CE20: null | CF20: null | CG20: null | CH20: null | CI20: null | CJ20: null | CK20: null | CL20: null | CM20: null | CN20: null | CO20: null | CP20: null | CQ20: null | CR20: null | CS20: null | CT20: null | CU20: null | CV20: null | CW20: null | CX20: null | CY20: null | CZ20: null | DA20: null | DB20: null | DC20: null | DD20: null | DE20: null | DF20: null | DG20: null | DH20: null | DI20: null | DJ20: null | DL20: =($DL$22-$DL$17)/5 + DL19 -> 157214.7 | DM20: null | DN20: null | DO20: null | DP20: null | DQ20: null | DR20: null | DS20: null | DT20: null | DU20: null | DV20: null | DW20: null | DX20: null | DY20: null | DZ20: null | EA20: null | EB20: null | EC20: null | ED20: null | EE20: null | EF20: null | EG20: null | EH20: null | EI20: null | EJ20: null | EK20: null | EL20: null | EM20: null | EN20: null | EO20: null | EP20: null | EQ20: null | ER20: null | ES20: null | ET20: null | EU20: null | EV20: null | EW20: null | EX20: null | EY20: null | EZ20: null | FA20: null | FB20: null | FC20: null | FD20: null | FE20: null | FF20: null
A21: 2014 | B21: null | C21: null | D21: null | E21: null | F21: null | G21: null | H21: null | I21: null | J21: null | K21: null | L21: null | M21: null | N21: null | O21: null | P21: null | Q21: null | R21: null | S21: null | T21: null | U21: null | V21: null | W21: null | X21: null | Y21: null | Z21: null | AA21: null | AB21: null | AC21: null | AD21: null | AE21: null | AF21: null | AG21: null | AH21: null | AI21: null | AJ21: null | AK21: null | AL21: null | AM21: null | AN21: null | AO21: null | AP21: null | AQ21: null | AR21: null | AS21: null | AT21: null | AU21: null | AV21: null | AW21: null | AX21: null | AY21: null | AZ21: null | BA21: null | BB21: null | BC21: null | BD21: null | BE21: null | BF21: null | BG21: null | BH21: null | BI21: null | BJ21: null | BK21: null | BL21: null | BM21: null | BN21: null | BO21: null | BP21: null | BQ21: null | BR21: null | BS21: null | BT21: null | BU21: null | BV21: null | BW21: null | BX21: null | BY21: null | BZ21: null | CA21: null | CB21: null | CC21: null | CD21: null | CE21: null | CF21: null | CG21: null | CH21: null | CI21: null | CJ21: null | CK21: null | CL21: null | CM21: null | CN21: null | CO21: null | CP21: null | CQ21: null | CR21: null | CS21: null | CT21: null | CU21: null | CV21: null | CW21: null | CX21: null | CY21: null | CZ21: null | DA21: null | DB21: null | DC21: null | DD21: null | DE21: null | DF21: null | DG21: null | DH21: null | DI21: null | DJ21: null | DL21: =($DL$22-$DL$17)/5 + DL20 -> 157237.44 | DM21: null | DN21: null | DO21: null | DP21: null | DQ21: null | DR21: null | DS21: null | DT21: null | DU21: null | DV21: null | DW21: null | DX21: null | DY21: null | DZ21: null | EA21: null | EB21: null | EC21: null | ED21: null | EE21: null | EF21: null | EG21: null | EH21: null | EI21: null | EJ21: null | EK21: null | EL21: null | EM21: null | EN21: null | EO21: null | EP21: null | EQ21: null | ER21: null | ES21: null | ET21: null | EU21: null | EV21: null | EW21: null | EX21: null | EY21: null | EZ21: null | FA21: null | FB21: null | FC21: null | FD21: null | FE21: null | FF21: null
A22: 2015 | B22: 450.35981431855737 | C22: 33.57268477439011 | D22: 470.5816893440679 | E22: 120.30175168479715 | F22: 486.8433851146974 | G22: 4056.6178971713343 | H22: 12.598975604215639 | I22: 0.31754597023881276 | J22: 11.575308747385588 | K22: 1.287201 | L22: 14.380799999999995 | M22: 107.00196859554904 | N22: 3.2502922615789016 | O22: 0.0542546961064026 | P22: 2.2894784 | Q22: 1.317664531821413 | R22: 12.508000000000008 | S22: 56.84608973803698 | T22: 7.234921946375448 | U22: 0 | V22: 17.958000399999992 | W22: 3.86625582778687 | X22: 16.262900000000013 | Y22: 69.70500040000002 | Z22: 11.050058140006577 | AA22: 3.1952660538934827 | AB22: 6.808000399999997 | AC22: 0.5430005999999998 | AD22: 6.854999999999997 | AE22: 56.844000400000006 | AF22: 65.1371628320872 | AG22: 2.212164242057685 | AH22: 108.40899999999998 | AI22: 18.800000599999994 | AJ22: 65.1 | AK22: 927.0000004000003 | AL22: 0.8167145163448785 | AM22: 0.40967286791079843 | AN22: 0.4549313999999999 | AO22: 0.44813226075605905 | AP22: 3.146414499999997 | AQ22: 12.331949886981235 | AR22: 10.3087410751781 | AS22: 1.0531616293909556 | AT22: 2.097667682 | AU22: 0.10200060000000004 | AV22: 8.513599999999999 | AW22: 51.913500599999985 | AX22: 22.08123072422334 | AY22: 7.5373056608001345 | AZ22: 2.9369048608075286 | BA22: 6.174165802996984 | BB22: 21.148271968974473 | BC22: 98.27578511557843 | BD22: 92.06467960551134 | BE22: 2.015689020447241 | BF22: 33.343900000000005 | BG22: 11.281148128539423 | BH22: 46.38900000000002 | BI22: 317.55300040000003 | BJ22: 72.92901695073317 | BK22: 3.5201392490823595 | BL22: 110.85491182656186 | BM22: 13.931942248584962 | BN22: 57.6863413999923 | BO22: 722.9000003999998 | BP22: 2.275046422719677 | BQ22: 0.041678314569269626 | BR22: 1.5389663999999998 | BS22: 0.21500139999999993 | BT22: 3.376999999999995 | BU22: 26.39300079999999 | BV22: 51.50353481426862 | BW22: 5.034853183035459 | BX22: 59.039 | BY22: 41.3260006 | BZ22: 102.50899999999994 | CA22: 676.3500003999997 | CB22: 2.481080899857317 | CC22: 0.12164336421688814 | CD22: 1.426717257084445 | CE22: 6.198134173005251 | CF22: 1.7531375542923335 | CG22: 0.7209773999999999 | CH22: 0.5606384493613551 | CI22: 2.2319999999999993 | CJ22: 13.542600600000002 | CK22: 1.5591258138980362 | CL22: 0.0741274891420644 | CM22: 0.2620012 | CN22: 0.8634470320598581 | CO22: 2.745543 | CP22: 24.865000600000016 | CQ22: 0.869961888416036 | CR22: 0.41800119999999985 | CS22: 0.10420805025339128 | CT22: 1.0928294004495047 | CU22: 7.321359060666724 | CV22: 3.5800138154020167 | CW22: 10.555669800000004 | CX22: 1.3874957747370755 | CY22: 17.813176500000008 | CZ22: 54.60300039999998 | DA22: 2.1143345320754205 | DB22: 0.1263508 | DC22: 0.539906461587028 | DD22: 2.504232339613567 | DE22: 17.760183640732773 | DF22: 0.8153360366794269 | DG22: 18.43944568886166 | DH22: 3.050207504191418 | DI22: 4.883554311138337 | DJ22: 139.50000039999998 | DK22: =SUM(DE22+DJ22) -> 157.26018 | DL22: =DK22*1000 -> 157260.18 | DM22: 7.577114541146648 | DN22: 0.03661730592883682 | DO22: 19.393042988322062 | DP22: 2.36587070004004 | DQ22: 10.295414860155592 | DR22: 78.34700040000003 | DS22: 9.559661421773361 | DT22: 0.22653441060804602 | DU22: 21.58739901310765 | DV22: 3.7030006 | DW22: 37.58000000000002 | DX22: 200.5700006000001 | DY22: 18.17604814150861 | DZ22: 0.6631251098650528 | EA22: 4.965652000000001 | EB22: 1.8435584967149894 | EC22: 6.575000000000002 | ED22: 84.46785791462881 | EE22: 6.60301446804406 | EF22: 0.0320891828348396 | EG22: 12.7730004 | EH22: 3.6510759402395454 | EI22: 17.47100000000001 | EJ22: 89.86636248053341 | EK22: 0.28595489937537505 | EL22: 0.6280012 | EM22: 0.3529018385540428 | EN22: 3.5760825660756344 | EO22: 25.99653357579791 | EP22: 0.6189235630913645 | EQ22: 3.6618005500000024 | ER22: 0.8085959870859505 | ES22: 5.367630450000003 | ET22: 27.531000600000006 | EU22: 9.301559236710773 | EV22: 0.13701999999999998 | EW22: 4.62982778702163 | EX22: 1.1610006 | EY22: 7.540000000000005 | EZ22: 66.29500060000001 | FA22: 16.86932500899038 | FB22: 6.196104351799243 | FC22: 15.240799999999997 | FD22: 0.9092429468568924 | FE22: 9.828202439240146 | FF22: 111.89551629094301
A23: 2016 | B23: null | C23: null | D23: null | E23: null | F23: null | G23: null | H23: null | I23: null | J23: null | K23: null | L23: null | M23: null | N23: null | O23: null | P23: null | Q23: null | R23: null | S23: null | T23: null | U23: null | V23: null | W23: null | X23: null | Y23: null | Z23: null | AA23: null | AB23: null | AC23: null | AD23: null | AE23: null | AF23: null | AG23: null | AH23: null | AI23: null | AJ23: null | AK23: null | AL23: null | AM23: null | AN23: null | AO23: null | AP23: null | AQ23: null | AR23: null | AS23: null | AT23: null | AU23: null | AV23: null | AW23: null | AX23: null | AY23: null | AZ23: null | BA23: null | BB23: null | BC23: null | BD23: null | BE23: null | BF23: null | BG23: null | BH23: null | BI23: null | BJ23: null | BK23: null | BL23: null | BM23: null | BN23: null | BO23: null | BP23: null | BQ23: null | BR23: null | BS23: null | BT23: null | BU23: null | BV23: null | BW23: null | BX23: null | BY23: null | BZ23: null | CA23: null | CB23: null | CC23: null | CD23: null | CE23: null | CF23: null | CG23: null | CH23: null | CI23: null | CJ23: null | CK23: null | CL23: null | CM23: null | CN23: null | CO23: null | CP23: null | CQ23: null | CR23: null | CS23: null | CT23: null | CU23: null | CV23: null | CW23: null | CX23: null | CY23: null | CZ23: null | DA23: null | DB23: null | DC23: null | DD23: null | DE23: null | DF23: null | DG23: null | DH23: null | DI23: null | DJ23: null | DL23: =($DL$27-$DL$22)/5 + DL22 -> 154276.42 | DM23: null | DN23: null | DO23: null | DP23: null | DQ23: null | DR23: null | DS23: null | DT23: null | DU23: null | DV23: null | DW23: null | DX23: null | DY23: null | DZ23: null | EA23: null | EB23: null | EC23: null | ED23: null | EE23: null | EF23: null | EG23: null | EH23: null | EI23: null | EJ23: null | EK23: null | EL23: null | EM23: null | EN23: null | EO23: null | EP23: null | EQ23: null | ER23: null | ES23: null | ET23: null | EU23: null | EV23: null | EW23: null | EX23: null | EY23: null | EZ23: null | FA23: null | FB23: null | FC23: null | FD23: null | FE23: null | FF23: null
A24: 2017 | B24: null | C24: null | D24: null | E24: null | F24: null | G24: null | H24: null | I24: null | J24: null | K24: null | L24: null | M24: null | N24: null | O24: null | P24: null | Q24: null | R24: null | S24: null | T24: null | U24: null | V24: null | W24: null | X24: null | Y24: null | Z24: null | AA24: null | AB24: null | AC24: null | AD24: null | AE24: null | AF24: null | AG24: null | AH24: null | AI24: null | AJ24: null | AK24: null | AL24: null | AM24: null | AN24: null | AO24: null | AP24: null | AQ24: null | AR24: null | AS24: null | AT24: null | AU24: null | AV24: null | AW24: null | AX24: null | AY24: null | AZ24: null | BA24: null | BB24: null | BC24: null | BD24: null | BE24: null | BF24: null | BG24: null | BH24: null | BI24: null | BJ24: null | BK24: null | BL24: null | BM24: null | BN24: null | BO24: null | BP24: null | BQ24: null | BR24: null | BS24: null | BT24: null | BU24: null | BV24: null | BW24: null | BX24: null | BY24: null | BZ24: null | CA24: null | CB24: null | CC24: null | CD24: null | CE24: null | CF24: null | CG24: null | CH24: null | CI24: null | CJ24: null | CK24: null | CL24: null | CM24: null | CN24: null | CO24: null | CP24: null | CQ24: null | CR24: null | CS24: null | CT24: null | CU24: null | CV24: null | CW24: null | CX24: null | CY24: null | CZ24: null | DA24: null | DB24: null | DC24: null | DD24: null | DE24: null | DF24: null | DG24: null | DH24: null | DI24: null | DJ24: null | DL24: =($DL$27-$DL$22)/5 + DL23 -> 151292.67 | DM24: null | DN24: null | DO24: null | DP24: null | DQ24: null | DR24: null | DS24: null | DT24: null | DU24: null | DV24: null | DW24: null | DX24: null | DY24: null | DZ24: null | EA24: null | EB24: null | EC24: null | ED24: null | EE24: null | EF24: null | EG24: null | EH24: null | EI24: null | EJ24: null | EK24: null | EL24: null | EM24: null | EN24: null | EO24: null | EP24: null | EQ24: null | ER24: null | ES24: null | ET24: null | EU24: null | EV24: null | EW24: null | EX24: null | EY24: null | EZ24: null | FA24: null | FB24: null | FC24: null | FD24: null | FE24: null | FF24: null
A25: 2018 | B25: null | C25: null | D25: null | E25: null | F25: null | G25: null | H25: null | I25: null | J25: null | K25: null | L25: null | M25: null | N25: null | O25: null | P25: null | Q25: null | R25: null | S25: null | T25: null | U25: null | V25: null | W25: null | X25: null | Y25: null | Z25: null | AA25: null | AB25: null | AC25: null | AD25: null | AE25: null | AF25: null | AG25: null | AH25: null | AI25: null | AJ25: null | AK25: null | AL25: null | AM25: null | AN25: null | AO25: null | AP25: null | AQ25: null | AR25: null | AS25: null | AT25: null | AU25: null | AV25: null | AW25: null | AX25: null | AY25: null | AZ25: null | BA25: null | BB25: null | BC25: null | BD25: null | BE25: null | BF25: null | BG25: null | BH25: null | BI25: null | BJ25: null | BK25: null | BL25: null | BM25: null | BN25: null | BO25: null | BP25: null | BQ25: null | BR25: null | BS25: null | BT25: null | BU25: null | BV25: null | BW25: null | BX25: null | BY25: null | BZ25: null | CA25: null | CB25: null | CC25: null | CD25: null | CE25: null | CF25: null | CG25: null | CH25: null | CI25: null | CJ25: null | CK25: null | CL25: null | CM25: null | CN25: null | CO25: null | CP25: null | CQ25: null | CR25: null | CS25: null | CT25: null | CU25: null | CV25: null | CW25: null | CX25: null | CY25: null | CZ25: null | DA25: null | DB25: null | DC25: null | DD25: null | DE25: null | DF25: null | DG25: null | DH25: null | DI25: null | DJ25: null | DL25: =($DL$27-$DL$22)/5 + DL24 -> 148308.91 | DM25: null | DN25: null | DO25: null | DP25: null | DQ25: null | DR25: null | DS25: null | DT25: null | DU25: null | DV25: null | DW25: null | DX25: null | DY25: null | DZ25: null | EA25: null | EB25: null | EC25: null | ED25: null | EE25: null | EF25: null | EG25: null | EH25: null | EI25: null | EJ25: null | EK25: null | EL25: null | EM25: null | EN25: null | EO25: null | EP25: null | EQ25: null | ER25: null | ES25: null | ET25: null | EU25: null | EV25: null | EW25: null | EX25: null | EY25: null | EZ25: null | FA25: null | FB25: null | FC25: null | FD25: null | FE25: null | FF25: null
